Workbook

Sheet 渠道培训中心基础信息
A1: 培训中心全称 | B1: 分公司 | C1: 区域 | D1: 名称变更 | E1: 服务签约公司名称 | F1: 渠道商等级 | G1: 培训中心教室信息 | H1: 培训样机说明 | I1: 培训中心地址 | J1: 培训中心电话 | K1: 培训中心培训对接人 （仅一个人，支持系统排班，含工号） | L1: 对接人邮箱 | M1: 对接人手机 | N1: 收款信息 | O1: 发票类型 | P1: 税率 | Q1: 备注
A2: 新疆九州通医疗科技有限公司 | B2: 新疆 | C2: 西北区 | G2: 教室面积，容纳人数 | H2: BC-75CRP*2 | I2: =IFERROR(_xlfn.XLOOKUP(A2,历史基础信息!$A$2:$A$52,历史基础信息!$D$2:$D$52,""),"") -> 新疆乌鲁木齐高新区（新市区）鲤鱼山北 路199号驰达-电子信息产业加速器1栋608号 | J2: =_xlfn.XLOOKUP(A2,历史基础信息!A:A,历史基础信息!E:E,"") -> 0991-3075000 | K2: =_xlfn.XLOOKUP(A2,历史基础信息!A:A,历史基础信息!F:F,"") -> 师灿灿 | L2: =_xlfn.XLOOKUP(A2,历史基础信息!A:A,历史基础信息!G:G,"") -> 1433825820@qq.com | M2: =_xlfn.XLOOKUP(A2,历史基础信息!A:A,历史基础信息!H:H,"") -> 13039457336 | N2: =_xlfn.XLOOKUP(A2,历史基础信息!A:A,历史基础信息!I:I,"") -> 单位名称:新疆中品医疗科技有限公司 税号: 91650104MA78W1CL2H 注册地址:新疆乌鲁木齐高新区（新市区）鲤鱼山北路199号驰达-电子信息产业加速器1栋501-504号 开户银行:招商银行乌鲁木齐北京路支行 账号: 991905464910601 行号:308881029067 | O2: =_xlfn.XLOOKUP(A2,历史基础信息!A:A,历史基础信息!J:J,"") -> 增值税专用发票/增值税普通发票：培训费 | P2: =_xlfn.XLOOKUP(A2,历史基础信息!A:A,历史基础信息!K:K,"") -> 0.06
A3: 兰州恺尔有商贸有限公司 | B3: 兰州 | C3: 西北区 | I3: =IFERROR(_xlfn.XLOOKUP(A3,历史基础信息!$A$2:$A$52,历史基础信息!$D$2:$D$52,""),"") -> 甘肃省兰州市城关区南滨河东路5198号名城广场1幢2单元14楼19室 | J3: =_xlfn.XLOOKUP(A3,历史基础信息!A:A,历史基础信息!E:E,"") -> 0931-8526183 | K3: =_xlfn.XLOOKUP(A3,历史基础信息!A:A,历史基础信息!F:F,"") -> 王洁 | L3: =_xlfn.XLOOKUP(A3,历史基础信息!A:A,历史基础信息!G:G,"") -> kry8526183@163.com | M3: =_xlfn.XLOOKUP(A3,历史基础信息!A:A,历史基础信息!H:H,"") -> 17797604947 | N3: =_xlfn.XLOOKUP(A3,历史基础信息!A:A,历史基础信息!I:I,"") -> 名称：兰州恺尔有商贸有限公司 税号：91627100MA7DC2JT0C 单位地址：甘肃省兰州市兰州新区绿地集团一期G地块渭河街3103号8A-19室 电话：09318526183 开户银行：中国建设银行兰州城关支行 银行账户：62050136000100001000 | O3: =_xlfn.XLOOKUP(A3,历史基础信息!A:A,历史基础信息!J:J,"") -> 增值税专用发票/增值税普通发票：维修费或维护费 | P3: =_xlfn.XLOOKUP(A3,历史基础信息!A:A,历史基础信息!K:K,"") -> 0.13
A4: 成都瑞坤科技有限公司 | B4: 成都 | C4: 西南区 | I4: =IFERROR(_xlfn.XLOOKUP(A4,历史基础信息!$A$2:$A$52,历史基础信息!$D$2:$D$52,""),"") -> 四川省成都市武侯区武科西四路99号金地威新科创园3栋3楼301室 | J4: =_xlfn.XLOOKUP(A4,历史基础信息!A:A,历史基础信息!E:E,"") -> 028-87799602 | K4: =_xlfn.XLOOKUP(A4,历史基础信息!A:A,历史基础信息!F:F,"") -> 陈宏 | L4: =_xlfn.XLOOKUP(A4,历史基础信息!A:A,历史基础信息!G:G,"") -> 103045739@qq.com | M4: =_xlfn.XLOOKUP(A4,历史基础信息!A:A,历史基础信息!H:H,"") -> 18782285187 | N4: =_xlfn.XLOOKUP(A4,历史基础信息!A:A,历史基础信息!I:I,"") -> 公司名：南充市顺庆区吉哆商务信息咨询服务部(个体工商户) 开户行：中国工商银行股份有限公司南充石油南路支 行 账 号：2315539209100080846 | O4: =_xlfn.XLOOKUP(A4,历史基础信息!A:A,历史基础信息!J:J,"") -> 增值税专用发票/增值税普通发票：维修费 | P4: =_xlfn.XLOOKUP(A4,历史基础信息!A:A,历史基础信息!K:K,"") -> 0.01
A5: 博实医疗保健（上海）有限公司 | B5: 上海 | C5: 华东区 | I5: =IFERROR(_xlfn.XLOOKUP(A5,历史基础信息!$A$2:$A$52,历史基础信息!$D$2:$D$52,""),"") -> 上海市奉贤区环城北路1099号 | J5: =_xlfn.XLOOKUP(A5,历史基础信息!A:A,历史基础信息!E:E,"") -> 021-61213287 | K5: =_xlfn.XLOOKUP(A5,历史基础信息!A:A,历史基础信息!F:F,"") -> 卞小姐 | L5: =_xlfn.XLOOKUP(A5,历史基础信息!A:A,历史基础信息!G:G,"") -> bianlili@boshi-diagnostics.com | M5: =_xlfn.XLOOKUP(A5,历史基础信息!A:A,历史基础信息!H:H,"") -> 13761291149 | N5: =_xlfn.XLOOKUP(A5,历史基础信息!A:A,历史基础信息!I:I,"") -> 公司名：博实医疗保健（上海）有限公司 地 址：上海市金山区金山卫镇秋实路688号9幢（金山新材料孵化器) 电 话：021-67181810 开户行：工商银行徐汇裕德路支行 账 号：1001270209300105185 | O5: =_xlfn.XLOOKUP(A5,历史基础信息!A:A,历史基础信息!J:J,"") -> 增值税专用发票/增值税普通发票：维修费或技术服务费 | P5: =_xlfn.XLOOKUP(A5,历史基础信息!A:A,历史基础信息!K:K,"") -> 13%或6%
A6: 广州艾维迪生物技术有限公司 | B6: 广州 | C6: 华南区 | I6: =IFERROR(_xlfn.XLOOKUP(A6,历史基础信息!$A$2:$A$52,历史基础信息!$D$2:$D$52,""),"") -> 广州市番禺区东环街天保路6号易事达大厦一楼105号 | J6: =_xlfn.XLOOKUP(A6,历史基础信息!A:A,历史基础信息!E:E,"") -> - | K6: =_xlfn.XLOOKUP(A6,历史基础信息!A:A,历史基础信息!F:F,"") -> 杨锦婵 | L6: =_xlfn.XLOOKUP(A6,历史基础信息!A:A,历史基础信息!G:G,"") -> 3601907146@qq.com | M6: =_xlfn.XLOOKUP(A6,历史基础信息!A:A,历史基础信息!H:H,"") -> 15322031002 | N6: =_xlfn.XLOOKUP(A6,历史基础信息!A:A,历史基础信息!I:I,"") -> 名称：广州艾维迪生物技术有限公司 纳税人识别号：91440101MA59TP8L3N 地址：广州市番禺区东环街天保路6号105铺之三 电话：020-31046729 开户行：中国银行广州番禺巨大产业园支行 帐号：645772162272 | O6: =_xlfn.XLOOKUP(A6,历史基础信息!A:A,历史基础信息!J:J,"") -> 增值税专用发票:培训服务票 | P6: =_xlfn.XLOOKUP(A6,历史基础信息!A:A,历史基础信息!K:K,"") -> 0.06
A7: 湖北瑞智达科技有限公司 | B7: 武汉 | C7: 华东区 | I7: =IFERROR(_xlfn.XLOOKUP(A7,历史基础信息!$A$2:$A$52,历史基础信息!$D$2:$D$52,""),"") -> 武汉市东西湖区金山达到1312号金海工业园6楼培训室 | J7: =_xlfn.XLOOKUP(A7,历史基础信息!A:A,历史基础信息!E:E,"") -> 027-83266623 | K7: =_xlfn.XLOOKUP(A7,历史基础信息!A:A,历史基础信息!F:F,"") -> 加燕楠 | L7: =_xlfn.XLOOKUP(A7,历史基础信息!A:A,历史基础信息!G:G,"") -> 1173256815@qq.com | M7: =_xlfn.XLOOKUP(A7,历史基础信息!A:A,历史基础信息!H:H,"") -> 19071020885 | N7: =_xlfn.XLOOKUP(A7,历史基础信息!A:A,历史基础信息!I:I,"") -> 武汉鑫瑞丰华科贸有限公司 开户行：中国工商银行武汉海关支行 帐号:3202 1230 1910 0016 820 | O7: =_xlfn.XLOOKUP(A7,历史基础信息!A:A,历史基础信息!J:J,"") -> 增值税专用发票/增值税普通发票：培训服务费 | P7: =_xlfn.XLOOKUP(A7,历史基础信息!A:A,历史基础信息!K:K,"") -> 0.06
A8: 广西铂泓生物科技有限公司 | B8: 南宁 | C8: 西南区 | I8: =IFERROR(_xlfn.XLOOKUP(A8,历史基础信息!$A$2:$A$52,历史基础信息!$D$2:$D$52,""),"") -> 广西壮族自治区南宁市良庆区中国（广西）自由贸易试验区南宁片区华威路 16 号南向电子信息产业园 3 号楼 4 楼A-01、A-02室 | J8: =_xlfn.XLOOKUP(A8,历史基础信息!A:A,历史基础信息!E:E,"") -> 0771-4972859 | K8: =_xlfn.XLOOKUP(A8,历史基础信息!A:A,历史基础信息!F:F,"") -> 万雨雯 | L8: =_xlfn.XLOOKUP(A8,历史基础信息!A:A,历史基础信息!G:G,"") -> 3984112127@qq.com | M8: =_xlfn.XLOOKUP(A8,历史基础信息!A:A,历史基础信息!H:H,"") -> 18777184023 | N8: =_xlfn.XLOOKUP(A8,历史基础信息!A:A,历史基础信息!I:I,"") -> 公司名：广西铂泓生物科技有限公司 地址：中国（广西）自由贸易试验区南宁片区凯旋路9号海尔青啤（东盟）联合广场2号楼五层503号办公室 电话：0771-4972859 开户行：中国光大银行股份有限公司南宁分行 账号：78890188000660007 | O8: =_xlfn.XLOOKUP(A8,历史基础信息!A:A,历史基础信息!J:J,"") -> 增值税专用发票/增值税普通发票：培训费/维修费 | P8: =_xlfn.XLOOKUP(A8,历史基础信息!A:A,历史基础信息!K:K,"") -> 6%/13%
A9: 四川国科康仪医疗科技有限公司 | B9: 成都 | C9: 西南区 | I9: =IFERROR(_xlfn.XLOOKUP(A9,历史基础信息!$A$2:$A$52,历史基础信息!$D$2:$D$52,""),"") -> 四川省成都市金牛区沙河源街道金丰路106号量力医药健康城7号楼12楼 | J9: =_xlfn.XLOOKUP(A9,历史基础信息!A:A,历史基础信息!E:E,"") -> 028-87776785 | K9: =_xlfn.XLOOKUP(A9,历史基础信息!A:A,历史基础信息!F:F,"") -> 敖春花 | L9: =_xlfn.XLOOKUP(A9,历史基础信息!A:A,历史基础信息!G:G,"") -> 309751765@qq.com | M9: =_xlfn.XLOOKUP(A9,历史基础信息!A:A,历史基础信息!H:H,"") -> 13678119175 | N9: =_xlfn.XLOOKUP(A9,历史基础信息!A:A,历史基础信息!I:I,"") -> 名称：四川世纪同昌医疗科技发展有限公司 地址：四川省成都市金牛区友联一街8号12楼1206-1208号 邮编：610000 电话：028-87579357 开户银行：成都银行抚琴支行 账号：1001300000983113 | O9: =_xlfn.XLOOKUP(A9,历史基础信息!A:A,历史基础信息!J:J,"") -> 增值税专用发票/增值税普通发票：服务费 | P9: =_xlfn.XLOOKUP(A9,历史基础信息!A:A,历史基础信息!K:K,"") -> 0.13
A10: 河南迈德瑞医疗服务供应链有限公司 | B10: 郑州 | C10: 西北区 | I10: =IFERROR(_xlfn.XLOOKUP(A10,历史基础信息!$A$2:$A$52,历史基础信息!$D$2:$D$52,""),"") -> 河南省郑州经济技术开发区第七大街188号院3号楼2楼 | J10: =_xlfn.XLOOKUP(A10,历史基础信息!A:A,历史基础信息!E:E,"") -> 0371-63827260 | K10: =_xlfn.XLOOKUP(A10,历史基础信息!A:A,历史基础信息!F:F,"") -> 黄晴 | L10: =_xlfn.XLOOKUP(A10,历史基础信息!A:A,历史基础信息!G:G,"") -> huangqing@hnmdr.com | M10: =_xlfn.XLOOKUP(A10,历史基础信息!A:A,历史基础信息!H:H,"") -> 15003856589 | N10: =_xlfn.XLOOKUP(A10,历史基础信息!A:A,历史基础信息!I:I,"") -> 公司名：河南迈德瑞医疗服务供应链有限公司 地 址：郑州经济技术开发区第七大街188号院3号楼2楼 邮 编：450000 电 话：0371-63827260 开户行：招商银行股份有限公司郑州经开区支行 账 号：371905274710802 | O10: =_xlfn.XLOOKUP(A10,历史基础信息!A:A,历史基础信息!J:J,"") -> 增值税专用发票/增值税普通发票：咨询服务费 | P10: =_xlfn.XLOOKUP(A10,历史基础信息!A:A,历史基础信息!K:K,"") -> 0.06
A11: 瑞帆（沈阳）医疗器械销售服务有限公司 | B11: 沈阳 | C11: 东北区 | I11: =IFERROR(_xlfn.XLOOKUP(A11,历史基础信息!$A$2:$A$52,历史基础信息!$D$2:$D$52,""),"") -> 辽宁省沈阳市于洪区吉力湖街 228-1 号（21 门、22 门） | J11: =_xlfn.XLOOKUP(A11,历史基础信息!A:A,历史基础信息!E:E,"") -> 15840345732 | K11: =_xlfn.XLOOKUP(A11,历史基础信息!A:A,历史基础信息!F:F,"") -> 常艳玲 | L11: =_xlfn.XLOOKUP(A11,历史基础信息!A:A,历史基础信息!G:G,"") -> 1359995947@qq.com | M11: =_xlfn.XLOOKUP(A11,历史基础信息!A:A,历史基础信息!H:H,"") -> 15840345732 | N11: =_xlfn.XLOOKUP(A11,历史基础信息!A:A,历史基础信息!I:I,"") -> 单位名称：沈阳雅努斯商贸有限公司 开 户 行：中国光大银行沈阳金城支行 账 号：75670188000258883 地 址：辽宁省沈阳市于洪区阳光路26-1号（202） 电 话：024-31226855 纳税人识别号：912101145734966210 | O11: =_xlfn.XLOOKUP(A11,历史基础信息!A:A,历史基础信息!J:J,"") -> 增值税专用发票/增值税普通发票：维修费或维护费 | P11: =_xlfn.XLOOKUP(A11,历史基础信息!A:A,历史基础信息!K:K,"") -> 0.06
A12: 浙江英特百善医疗设备有限公司 | B12: 杭州 | C12: 华东区 | I12: =IFERROR(_xlfn.XLOOKUP(A12,历史基础信息!$A$2:$A$52,历史基础信息!$D$2:$D$52,""),"") -> 浙江省杭州市西湖区蒋村街道双龙街239号西投创智中心1号楼5层502室 | J12: =_xlfn.XLOOKUP(A12,历史基础信息!A:A,历史基础信息!E:E,"") -> 0571-87131103 | K12: =_xlfn.XLOOKUP(A12,历史基础信息!A:A,历史基础信息!F:F,"") -> 金芳 | L12: =_xlfn.XLOOKUP(A12,历史基础信息!A:A,历史基础信息!G:G,"") -> 1182784991@qq.com | M12: =_xlfn.XLOOKUP(A12,历史基础信息!A:A,历史基础信息!H:H,"") -> 17857071365 | N12: =_xlfn.XLOOKUP(A12,历史基础信息!A:A,历史基础信息!I:I,"") -> 公司名称： 浙江英特百善医疗设备有限公司 税务登记号：91330106079348885U 税务登记地址：浙江省杭州市西湖区蒋村街道双龙街239号西投创智中心1号楼5层502室 税务登记电话：0571-87131103 税务登记开户银行名称：中国工商银行股份有限公司杭州古墩路支行 税务登记银行账号：1202224909900169993 百善开户行行号：102331002495 | O12: =_xlfn.XLOOKUP(A12,历史基础信息!A:A,历史基础信息!J:J,"") -> 增值税专用发票 | P12: =_xlfn.XLOOKUP(A12,历史基础信息!A:A,历史基础信息!K:K,"") -> 0.06
A13: 广西讴健供应链管理集团有限公司 | B13: 南宁 | C13: 西南区 | I13: =IFERROR(_xlfn.XLOOKUP(A13,历史基础信息!$A$2:$A$52,历史基础信息!$D$2:$D$52,""),"") -> 南宁市江南区金凯路106号联东U谷南宁经开科技港标准厂房16号厂房5楼 | J13: =_xlfn.XLOOKUP(A13,历史基础信息!A:A,历史基础信息!E:E,"") -> 0771-4891028 | K13: =_xlfn.XLOOKUP(A13,历史基础信息!A:A,历史基础信息!F:F,"") -> 郭尧 | L13: =_xlfn.XLOOKUP(A13,历史基础信息!A:A,历史基础信息!G:G,"") -> pxzx@ojscg.com | M13: =_xlfn.XLOOKUP(A13,历史基础信息!A:A,历史基础信息!H:H,"") -> 19977196114 | N13: =_xlfn.XLOOKUP(A13,历史基础信息!A:A,历史基础信息!I:I,"") -> 公司名称：广西讴健供应链管理集团有限公司 地址：南宁市金凯路106号联东U谷南宁经开科技港标准厂房16号厂房101号房 邮 编：530031 电话：0771-4891028 开户行：中国银行南宁市桃源支行 账 号：618482498077 | O13: =_xlfn.XLOOKUP(A13,历史基础信息!A:A,历史基础信息!J:J,"") -> 增值税专用发票/增值税普通发票：维修费或维护费 | P13: =_xlfn.XLOOKUP(A13,历史基础信息!A:A,历史基础信息!K:K,"") -> 0.03
A14: 河南晟宝电子技术有限公司 | B14: 郑州 | C14: 西北区 | I14: =IFERROR(_xlfn.XLOOKUP(A14,历史基础信息!$A$2:$A$52,历史基础信息!$D$2:$D$52,""),"") -> 河南省郑州市高新区莲花街联东U谷-郑州高新国际企业港18号-2号楼501 | J14: =_xlfn.XLOOKUP(A14,历史基础信息!A:A,历史基础信息!E:E,"") -> 0371-55919089 | K14: =_xlfn.XLOOKUP(A14,历史基础信息!A:A,历史基础信息!F:F,"") -> 汪晓锋 | L14: =_xlfn.XLOOKUP(A14,历史基础信息!A:A,历史基础信息!G:G,"") -> 863637991@qq.com | M14: =_xlfn.XLOOKUP(A14,历史基础信息!A:A,历史基础信息!H:H,"") -> 15890058791 | N14: =_xlfn.XLOOKUP(A14,历史基础信息!A:A,历史基础信息!I:I,"") -> 开票资料 单 位 名 称：河南晟宝电子技术有限公司 纳税人识别号：91410100MA3X9WQH3B 地 址、电 话：河南省郑州市高新区莲花街联东U谷-郑州高新国际企业港18号-2号楼401 0371-55919089 开户行及账号：中国银行股份有限公司郑州高新技术开发区支行258549558281 | O14: =_xlfn.XLOOKUP(A14,历史基础信息!A:A,历史基础信息!J:J,"") -> 增值税专用发票/技术服务费 | P14: =_xlfn.XLOOKUP(A14,历史基础信息!A:A,历史基础信息!K:K,"") -> 0.06
... A52: 昆明康骐科技有限公司 | B52: 昆明 | C52: 西南区 | I52: =IFERROR(_xlfn.XLOOKUP(A52,历史基础信息!$A$2:$A$52,历史基础信息!$D$2:$D$52,""),"") -> 云南省昆明市五华区科普路与王筇路交叉口绿地 云都会广场A地块1栋B区创海大厦18层1811室1812室 | J52: =_xlfn.XLOOKUP(A52,历史基础信息!A:A,历史基础信息!E:E,"") -> 0871-65386168 | K52: =_xlfn.XLOOKUP(A52,历史基础信息!A:A,历史基础信息!F:F,"") -> 罗美娥 | L52: =_xlfn.XLOOKUP(A52,历史基础信息!A:A,历史基础信息!G:G,"") -> 13759187313@139.com | M52: =_xlfn.XLOOKUP(A52,历史基础信息!A:A,历史基础信息!H:H,"") -> 13759187313 | N52: =_xlfn.XLOOKUP(A52,历史基础信息!A:A,历史基础信息!I:I,"") -> 公司名称:昆明康骐科技有限公司 税号:91530112MA6K7Q603B 开户行:中国建设银行昆明西山支行 账号:53050161633600000120 注册地址:云南省昆明市五华区科普路与王筇路交叉口绿地 云都会广场A地块1栋B区创海大厦18层1811室1812室 电话:0871-65386168 | O52: =_xlfn.XLOOKUP(A52,历史基础信息!A:A,历史基础信息!J:J,"") -> 增值税专用发票/增值税普通发票：维修费或维护费 | P52: =_xlfn.XLOOKUP(A52,历史基础信息!A:A,历史基础信息!K:K,"") -> 0.03
A53: 重庆瑞智盟 | B53: 重庆 | C53: 西南区

Sheet Sheet1
A1: 培训中心全称 | B1: 分公司 | C1: 区域 | D1: 名称变更 | E1: 服务签约公司名称 | F1: 渠道商等级 | G1: 培训中心教室信息 | H1: 培训样机说明 | I1: 培训中心地址 | J1: 培训中心电话 | K1: 培训中心培训对接人 （仅一个人，支持系统排班，含工号） | L1: 对接人邮箱 | M1: 对接人手机 | N1: 收款信息 | O1: 发票类型 | P1: 税率 | Q1: 备注
A2: 新疆九州通医疗科技有限公司 | B2: 新疆 | C2: 西北区 | E2: 新疆九州通医疗服务有限公司 | F2: V3.0 | G2: 教室面积80平方，容纳人数40人 | H2: BC-75CRP*2 | I2: 新疆乌鲁木齐高新区（新市区）鲤鱼山北 路199号驰达-电子信息产业加速器1栋608号 | J2: 0991-3075000 | K2: 师灿灿 | L2: 1433825820@qq.com | M2: 13039457336 | N2: 单位名称:新疆中品医疗科技有限公司 税号: 91650104MA78W1CL2H 注册地址:新疆乌鲁木齐高新区（新市区）鲤鱼山北路199号驰达-电子信息产业加速器1栋501-504号 开户银行:招商银行乌鲁木齐北京路支行 账号: 991905464910601 行号:308881029067 | O2: 增值税专用发票/增值税普通发票：培训费 | P2: 0.06
A3: 兰州恺尔有商贸有限公司 | B3: 兰州 | C3: 西北区 | I3: 甘肃省兰州市城关区南滨河东路5198号名城广场1幢2单元14楼19室 | J3: 0931-8526183 | K3: 王洁 | L3: kry8526183@163.com | M3: 17797604947 | N3: 名称：兰州恺尔有商贸有限公司 税号：91627100MA7DC2JT0C 单位地址：甘肃省兰州市兰州新区绿地集团一期G地块渭河街3103号8A-19室 电话：09318526183 开户银行：中国建设银行兰州城关支行 银行账户：62050136000100001000 | O3: 增值税专用发票/增值税普通发票：维修费或维护费 | P3: 0.13
A4: 成都瑞坤科技有限公司 | B4: 成都 | C4: 西南区 | I4: 四川省成都市武侯区武科西四路99号金地威新科创园3栋3楼301室 | J4: 028-87799602 | K4: 陈宏 | L4: 103045739@qq.com | M4: 18782285187 | N4: 公司名：南充市顺庆区吉哆商务信息咨询服务部(个体工商户) 开户行：中国工商银行股份有限公司南充石油南路支 行 账 号：2315539209100080846 | O4: 增值税专用发票/增值税普通发票：维修费 | P4: 0.01
A5: 博实医疗保健（上海）有限公司 | B5: 上海 | C5: 华东区 | I5: 上海市奉贤区环城北路1099号 | J5: 021-61213287 | K5: 卞小姐 | L5: bianlili@boshi-diagnostics.com | M5: 13761291149 | N5: 公司名：博实医疗保健（上海）有限公司 地 址：上海市金山区金山卫镇秋实路688号9幢（金山新材料孵化器) 电 话：021-67181810 开户行：工商银行徐汇裕德路支行 账 号：1001270209300105185 | O5: 增值税专用发票/增值税普通发票：维修费或技术服务费 | P5: 13%或6%
A6: 广州艾维迪生物技术有限公司 | B6: 广州 | C6: 华南区 | I6: 广州市番禺区东环街天保路6号易事达大厦一楼105号 | J6: - | K6: 杨锦婵 | L6: 3601907146@qq.com | M6: 15322031002 | N6: 名称：广州艾维迪生物技术有限公司 纳税人识别号：91440101MA59TP8L3N 地址：广州市番禺区东环街天保路6号105铺之三 电话：020-31046729 开户行：中国银行广州番禺巨大产业园支行 帐号：645772162272 | O6: 增值税专用发票:培训服务票 | P6: 0.06
A7: 湖北瑞智达科技有限公司 | B7: 武汉 | C7: 华东区 | I7: 武汉市东西湖区金山达到1312号金海工业园6楼培训室 | J7: 027-83266623 | K7: 加燕楠 | L7: 1173256815@qq.com | M7: 19071020885 | N7: 武汉鑫瑞丰华科贸有限公司 开户行：中国工商银行武汉海关支行 帐号:3202 1230 1910 0016 820 | O7: 增值税专用发票/增值税普通发票：培训服务费 | P7: 0.06
A8: 广西铂泓生物科技有限公司 | B8: 南宁 | C8: 西南区 | I8: 广西壮族自治区南宁市良庆区中国（广西）自由贸易试验区南宁片区华威路 16 号南向电子信息产业园 3 号楼 4 楼A-01、A-02室 | J8: 0771-4972859 | K8: 万雨雯 | L8: 3984112127@qq.com | M8: 18777184023 | N8: 公司名：广西铂泓生物科技有限公司 地址：中国（广西）自由贸易试验区南宁片区凯旋路9号海尔青啤（东盟）联合广场2号楼五层503号办公室 电话：0771-4972859 开户行：中国光大银行股份有限公司南宁分行 账号：78890188000660007 | O8: 增值税专用发票/增值税普通发票：培训费/维修费 | P8: 6%/13%
A9: 四川国科康仪医疗科技有限公司 | B9: 成都 | C9: 西南区 | I9: 四川省成都市金牛区沙河源街道金丰路106号量力医药健康城7号楼12楼 | J9: 028-87776785 | K9: 敖春花 | L9: 309751765@qq.com | M9: 13678119175 | N9: 名称：四川世纪同昌医疗科技发展有限公司 地址：四川省成都市金牛区友联一街8号12楼1206-1208号 邮编：610000 电话：028-87579357 开户银行：成都银行抚琴支行 账号：1001300000983113 | O9: 增值税专用发票/增值税普通发票：服务费 | P9: 0.13
A10: 河南迈德瑞医疗服务供应链有限公司 | B10: 郑州 | C10: 西北区 | I10: 河南省郑州经济技术开发区第七大街188号院3号楼2楼 | J10: 0371-63827260 | K10: 黄晴 | L10: huangqing@hnmdr.com | M10: 15003856589 | N10: 公司名：河南迈德瑞医疗服务供应链有限公司 地 址：郑州经济技术开发区第七大街188号院3号楼2楼 邮 编：450000 电 话：0371-63827260 开户行：招商银行股份有限公司郑州经开区支行 账 号：371905274710802 | O10: 增值税专用发票/增值税普通发票：咨询服务费 | P10: 0.06
A11: 瑞帆（沈阳）医疗器械销售服务有限公司 | B11: 沈阳 | C11: 东北区 | I11: 辽宁省沈阳市于洪区吉力湖街 228-1 号（21 门、22 门） | J11: 15840345732 | K11: 常艳玲 | L11: 1359995947@qq.com | M11: 15840345732 | N11: 单位名称：沈阳雅努斯商贸有限公司 开 户 行：中国光大银行沈阳金城支行 账 号：75670188000258883 地 址：辽宁省沈阳市于洪区阳光路26-1号（202） 电 话：024-31226855 纳税人识别号：912101145734966210 | O11: 增值税专用发票/增值税普通发票：维修费或维护费 | P11: 0.06
A12: 浙江英特百善医疗设备有限公司 | B12: 杭州 | C12: 华东区 | I12: 浙江省杭州市西湖区蒋村街道双龙街239号西投创智中心1号楼5层502室 | J12: 0571-87131103 | K12: 金芳 | L12: 1182784991@qq.com | M12: 17857071365 | N12: 公司名称： 浙江英特百善医疗设备有限公司 税务登记号：91330106079348885U 税务登记地址：浙江省杭州市西湖区蒋村街道双龙街239号西投创智中心1号楼5层502室 税务登记电话：0571-87131103 税务登记开户银行名称：中国工商银行股份有限公司杭州古墩路支行 税务登记银行账号：1202224909900169993 百善开户行行号：102331002495 | O12: 增值税专用发票 | P12: 0.06
A13: 广西讴健供应链管理集团有限公司 | B13: 南宁 | C13: 西南区 | I13: 南宁市江南区金凯路106号联东U谷南宁经开科技港标准厂房16号厂房5楼 | J13: 0771-4891028 | K13: 郭尧 | L13: pxzx@ojscg.com | M13: 19977196114 | N13: 公司名称：广西讴健供应链管理集团有限公司 地址：南宁市金凯路106号联东U谷南宁经开科技港标准厂房16号厂房101号房 邮 编：530031 电话：0771-4891028 开户行：中国银行南宁市桃源支行 账 号：618482498077 | O13: 增值税专用发票/增值税普通发票：维修费或维护费 | P13: 0.03
A14: 河南晟宝电子技术有限公司 | B14: 郑州 | C14: 西北区 | I14: 河南省郑州市高新区莲花街联东U谷-郑州高新国际企业港18号-2号楼501 | J14: 0371-55919089 | K14: 汪晓锋 | L14: 863637991@qq.com | M14: 15890058791 | N14: 开票资料 单 位 名 称：河南晟宝电子技术有限公司 纳税人识别号：91410100MA3X9WQH3B 地 址、电 话：河南省郑州市高新区莲花街联东U谷-郑州高新国际企业港18号-2号楼401 0371-55919089 开户行及账号：中国银行股份有限公司郑州高新技术开发区支行258549558281 | O14: 增值税专用发票/技术服务费 | P14: 0.06
A15: 安徽赛威思医疗供应链服务有限公司 | B15: 合肥 | C15: 华东区 | I15: 安徽省合肥市包河区上海路18号淮仁堂4楼8401室 | J15: 0551-62680075 | K15: 胡娟 | L15: 18712179581@163.com | M15: 18712179581 | N15: 公司名称：安徽赛威思医疗供应链服务有限公司 地 址：安徽省合肥市包河区上海路18号淮仁堂4楼8401室 邮 编：230000 电 话：0551-62680075 开户行：中国建设银行合肥银杏苑支行 账 号：34050145090600000167 | O15: 增值税专用发票/增值税普通发票：服务费或技术服务费 | P15: 0.06
A16: 科海同业河北医疗器械贸易有限公司 | B16: 石家庄 | C16: 华北区 | I16: 河北省石家庄市桥西区新石中路375号金石大厦C座7楼 | J16: 31183809982 | K16: 刘刚 | L16: 469997060@qq.com | M16: 17732120400 | N16: 科海同业河北医疗器械贸易有限公司开票信息 公司名称：科海同业河北医疗器械贸易有限公司 开户行：建行石家庄红旗大街支行 账 号：13050161560800000996 税 号：91130104MA0CX2RJ07 地 址：河北省石家庄市桥西区新石中路375号金石大厦C座7楼722-726室 电 话：0311-83809982 | O16: 增值税专用发票/增值税普通发票：维修费或技术服务咨询 | P16: 0.06
A17: 四川瑞孚医疗科技股份有限公司 | B17: 成都 | C17: 西南区 | I17: 成都市锦江区创意工业园毕昇路468号创世纪大厦1栋30层 | J17: 18349375258 | K17: 王春艳 | L17: 936051093@qq.com | M17: 18349375258 | N17: 户名：四川瑞孚医疗科技股份有限公司 开户行：成都银行股份有限公司锦江工业园支行 银行账号：1001300001082677 纳税人识别号：91510100MAC4G1J97E 公司地址：四川省成都市锦江区创意工业园毕昇路466号、468号1栋30层1号 公司电话：028-85212668 | O17: 增值税专用发票：服务费或技术服务费 | P17: 0.06
A18: 甘肃赣陇医疗科技有限公司 | B18: 兰州 | C18: 西北区 | I18: 甘肃省兰州市安宁区沙井驿街道北滨河西路1272号（兰州国际家居建材博览城B1区第9幢301室） | J18: 15379020517 | K18: 程生宝 | L18: 2479419728@qq.com | M18: 15379020517 | N18: 公司名：甘肃赣陇医疗科技有限公司 地 址：甘肃省兰州市七里河区中天健11栋2201室 邮 编：730050 电 话：0931-7894298 开户行：交通银行兰州七里河支行 账 号：621060108013000133112 | O18: 增值税专用发票/增值税普通发票：培训费 | P18: 0.06
A19: 西安尚肯电子科技有限公司 | B19: 西安 | C19: 西北区 | I19: 陕西省西安市雁塔区高新区团结南路12号西安国际人才大厦A座1001室 | J19: 029-88451665 | K19: 成年 | L19: 1183439346@qq.com | M19: 18840389808 | N19: 公司名：西安尚肯电子科技有限公司 地 址：西安市高新区唐延南路十一号3幢1单元11627室 税号：9161 0131 3224 0244 08 邮 编：710000 电 话：029－88451665 开户行：中国银行股份有限公司西安逸翠园支行 账 号：1024 5129 5214 | O19: 培训费，专票 | P19: 0.06
A20: 四川精晶科技发展有限责任公司 | B20: 成都 | C20: 西南区 | I20: 四川省成都市金牛区蜀西路42号三泰魔方B2栋904室 | J20: 028-83178198 | K20: 臧鹏 | L20: 113317031@QQ.COM | M20: 13550241780 | O20: 增值税专用发票/增值税普通发票：维修费 | P20: 0.13
A21: 广东美馗生物技术有限公司 | B21: 广州 | C21: 华南区 | I21: 广东省广州市番禺区南村镇兴业大道488号群兴科创园A栋307室 | J21: 020-31052118 | K21: 区伟民 | L21: 499674663@QQ.com | M21: 13602820901 | N21: 公司名：广东美馗生物技术有限公司 地 址：广州市番禺区市桥街兴泰路264号基盛万科大厦A栋602室 邮 编：511400 电 话：02031052118 开户行：中国工商银行股份有限公司广州大石支行 账 号：3602074819100483913 | O21: 增税专票/普票 | P21: 0.06
A22: 吉林省鸿嘉医疗器械有限公司 | B22: 黑吉 | C22: 东北区 | I22: 吉林省长春市宽城区龙腾路1377号汇酉生物五楼会议室 | J22: 0431-88922378 | K22: 王颖 | L22: cchlkj@163.com | M22: 15584329559 | N22: 公司名称：吉林省鸿嘉医疗器械有限公司税 号：9122 0104 6833 7279 36开 户 行：中国工商银行长春同志街支行账 号：4200 2291 0920 0051 752 | O22: 增值税专用发票/增值税普通发票：维修费、服务费或现代服务 | P22: 13%或6%
A23: 辽宁医工技术服务有限公司 | B23: 沈阳 | C23: 东北区 | I23: 辽宁省沈阳市和平区文艺路11号902 | J23: 024-25258227 | K23: 田佳鹭 | L23: 2531008545@qq.com | M23: 18741035493 | N23: 公 司：辽宁医工技术服务有限公司 地 址：沈阳市和平区文艺路11号902 邮 编：110001 电 话：024-25258227 开户行：中国民生银行股份有限公司沈阳青年大街支行 账 号：641894345 | O23: 增值税专用发票/增值税普通发票：维修费或维护费 | P23: 0.06
A24: 辽宁九诺生物科技有限公司 | B24: 沈阳 | C24: 东北区 | I24: 沈阳市浑南区朗日街22号1门 | J24: 024-31810269 | K24: 张伟华 | L24: 122381661@qq.com | M24: 13130478603 | N24: 名称:沈阳卓康商贸有限公司 帐号：0618 4001 0400 23398 开户行：农业银行沈阳兴华支行 行号：103221018405 | O24: 增值税专用发票/增值税普通发票：维修费或维护费 | P24: 0.13
A25: 杭州华景医疗科技有限公司 | B25: 杭州 | C25: 华东区 | I25: 浙江省杭州市萧山区萧山经济技术开 发区启迪路 198 号 B1-1001-01 室 | J25: 15067157785 | K25: 金冠盛 | L25: hzxsjgs@163.com | M25: 15067157785 | N25: 单位全称 杭州华景医疗科技有限公司 税号 91330108MA28NFUK9G 开户银行 杭州银行萧山城厢支行 银行账号 3301040160016610662 地址 浙江省杭州市萧山区萧山经济技术开 发区启迪路 198 号 B1-1001-01 室 电话 0571-86712990 | O25: 增值税专用发票/增值税普通发票：服务费或技术服务费 | P25: 0.06
A26: 北京东南仪诚实验室设备有限公司 | B26: 北京 | C26: 华北区 | I26: 北京市海淀区杏石口路30号A区119号 | J26: 13311118969 | K26: 王川 | L26: 24160300@qq.com | M26: 13311118969 | N26: 公司名：北京东南仪诚实验室设备有限公司 地 址：北京市海淀区杏石口路30号A区307号 010-51668855 邮编：100195 税 号：911101087393532696 开户行及账号：工行西直门支行0200065009200031207 行号：102100006502 | O26: 增值税专用发票/增值税普通发票：咨询服务 | P26: 0.06
A27: 河北钧溢祥医疗科技有限公司 | B27: 石家庄 | C27: 华北区 | I27: 河北省唐山市高新技术产业园区火炬路410号联东U谷产业园10#-1 214-1 | K27: 肖付 | L27: 564246333@qq.com | M27: 18716075943 | N27: 河北钧溢祥医疗科技有限公司 纳税人识别号：91130293MACKWRQ19Q 地址：河北省唐山市高新技术产业园区火炬路410号联东U谷产业园10#-1 214-1 邮 编：063009 电话：131 8042 6580 开户行：招商银行股份有限公司唐山高新区支行 账号：315901218310701 联系人: 毛春媛 15175585716 | O27: 增值税专用发票/增值税普通发票：维修费或维护费 | P27: 0.03
A28: 江西吉迈医疗科技有限公司 | B28: 南昌 | C28: 华南区 | I28: 江西省南昌市青山湖区北山路259号塞维莱科技城B10栋1楼 | J28: 0791-88107699 | K28: 胡威 | L28: 348933088@qq.com | M28: 13870966433 | N28: 公司名称：江西吉迈医疗科技有限公司 地址：南昌市青山湖区北山路259号塞维莱科技园B10栋 邮编：332000 电话：0791-88107699 开户行：邮储银行洪城大市场支行 帐号：936007010013318895 | O28: 增值税专用发票/增值税普通发票：维修费或维护费
A29: 湖南康锦元科技有限公司 | B29: 长沙 | C29: 华南区 | I29: 湖南省长沙市岳麓区麓松路489号海凭国际大厦C2栋818室 | J29: 0731-86459660 | K29: 徐锋彬 | L29: ykylpx@163.com | M29: 13574115681 | N29: 公司名：湖南康锦元科技有限公司 地址：长沙高新开发区谷苑路229号海凭园2栋813房 邮编：410000 电话：0731-88805296 开户行：湖南银行股份有限公司长沙东塘支行 8121 0309 0000 07567 | O29: 增值税专用发票/增值税普通发票：培训费 | P29: 0.06
A30: 海南凯曼生物科技有限公司 | B30: 海南 | C30: 华南区 | I30: 海南省海口市龙华区南海大道100号美国工业村2-7单元二楼 | J30: 0898-68545586 | K30: 符业明 | L30: 332101335@qq.com | M30: 13876685747 | N30: 单位：海南凯曼生物科技有限公司 银行：中国工商银行股份有限公司海口海秀支行 银行帐号：2201021009200141553 纳税号： 91460000MA5TBBRF74 | O30: 增值税专用发票/增值税普通发票：维修费或技术服务费 | P30: 0.13
A31: 深圳市迈加生物医疗有限公司 | B31: 深圳 | C31: 华南区 | I31: 广东省惠州市云山西路2号（帝景国际商务中心C座1925室） | J31: 0755-23774060 | K31: 詹君 | L31: 823226784@qq.com | M31: 18123650463 | N31: 公司名：深圳市迈加生物医疗有限公司 地址：深圳市前海深港合作区前湾一路1号A栋201室（入驻深圳市前海商务秘书有限公司） 邮编：518000 电话：0755-23764330 开户行：中国农业银行深圳八卦岭支行 账号：41004800040024027 | O31: 增值税专用发票/增值税普通发票：服务费、技术咨询费 | P31: 0.06
A32: 济南逸兴恒运电子科技有限公司 | B32: 济南 | C32: 华北区 | I32: 山东省济南市历下区华夏福地3号楼1单元201室 | J32: 0531-82916508 | K32: 王辉 | L32: wh163631@163.com | M32: 18660812091 | N32: 公司名：山东智信医疗设备有限公司 地 址：山东省济南市商河县玉皇庙镇白玉路与玉皇路交叉口公交始末站3楼311室 邮 编：251600 电 话：0531-82916508 开户行：招商银行股份有限公司济南解放路支行 账 号：531905488710401 | O32: 增值税专用发票：培训费 | P32: 0.06
A33: 内蒙古众智医工技术服务有限公司 | B33: 内蒙古 | C33: 东北区 | I33: 内蒙古呼和浩特市新城区腾飞北路15号606室 | J33: 13847134917 | K33: 杨晨光 | L33: 767160131@qq.com | M33: 15148213495 | N33: 公司名称：内蒙古众智医工技术服务有限公司 纳税人识别号：91150105MA7FNGEF4T 银行账号：4719 0219 6110 801 开户行：招商银行股份有限公司呼和浩特分行营业部 行号：3081 9103 6114 地址：内蒙古自治区呼和浩特市赛罕区绿地领海大厦B座1109 电话：18347407450 邮编010000 | O33: 增值税专用发票/增值税普通发票：维修费或维护费 | P33: 0.03
A34: 云南晟新达医疗器械有限公司 | B34: 昆明 | C34: 西南区 | I34: 云南省昆明市盘龙区北京路延长线住佳商宇4幢8层2号 | J34: 0871-65382116 | K34: 熊济 | L34: 363377906@qq.com | M34: 13888203183 | N34: 公司名：云南靖都医疗器械有限公司 地 址：云南省昆明市盘龙区北京路延长线住佳商宇4幢8层2号 邮 编：650000 电 话：0871-65382116 开户行：中国建设银行股份有限公司昆明凤凰城支行 账 号：53050190504000000013 | O34: 增值税专用发票/增值税普通发票：维修费或维护费 | P34: 0.13
A35: 成都泓然明吉商贸有限公司 | B35: 成都 | C35: 西南区 | I35: 成都市青羊区光华北五路266号新兴产业示范大厦3栋11楼 | J35: 028-86150103 | K35: 唐萍 | L35: cdhrmj@126.com | M35: 15823546260 | N35: 名称：成都泓然明吉商贸有限公司 纳税人识别号：91510105350558848T 地址、电话：成都市青羊区蜀金路1号3栋19层1905号 86150103 开户行及帐号：招商银行成都分行金沙支行 128906494810101 | O35: 增值税专用发票/增值税普通发票：维修费或维护费 | P35: 0.13
A36: 南京贝登医疗股份有限公司 | B36: 南京 | C36: 华东区 | I36: 江苏省南京市秦淮区永丰大道36号01栋10楼 | J36: 025-68538253 | K36: 刘会奇 | L36: simba.liu@vedeng.com | M36: 13913040353 | N36: 公司名：南京贝登医疗股份有限公司 地址：南京市秦淮区永顺路2号2幢三楼301室 邮编：210014 电 话：025-68538253 开户行： 中国建设银行江苏南京中山南路支行 账号： 32001881236052503686 | O36: 增值税普通发票：维修费或维护费 | P36: 0.03
A37: 郑州青旭医疗科技有限公司 | B37: 郑州 | C37: 西北区 | I37: 河南省郑州市管城回族区经开第七大街与经北四路交叉口188号院北楼4楼407室 | J37: 0371-66337061 | K37: 郭啸 | L37: 18614962807@163.com | M37: 18614962807 | N37: 单位名称：郑州青旭医疗科技有限公司 税号：91410104MA9G002781 地址：河南省郑州市管城回族区城东南路55号2号楼2层209号 电话：13213261005 银行名称：招商银行股份有限公司郑州二里岗支行 账号：371908013610902 | O37: 增值税专用发票/增值税普通发票 | P37: 0.06
A38: 沈阳柏诺医疗电子科技有限公司 | B38: 沈阳 | C38: 东北区 | I38: 辽宁省沈阳市浑南区浑南二路6-28号1801 | J38: 024-31607646 | K38: 李丹 | L38: 524063673@qq.com | M38: 15998351074 | N38: 公司名称：沈阳柏诺医疗电子科技有限公司 纳税人识别号：91210112MA7JNT3C93 地址：辽宁省沈阳市浑南区浑南二路6-28号（1-18-1、1-18-11） 电话：13904050810 开户行：招商银行股份有限公司沈阳新世界支行 账号：124910013710301 | O38: 增值税专用发票/增值税普通发票：维修费或维护费 | P38: 0.13
A39: 安徽蓝创生物科技有限公司 | B39: 合肥 | C39: 华东区 | I39: 安徽省合肥市蜀山区科学大道与合欢路交口合创产业园7D | J39: 0551-64466966 | K39: 李龙 | L39: 812640480@qq.com | M39: 17333079798 | N39: 安徽蓝创生物科技有限公司 税 号：91340111MA2TU3PJ33 地 址：安徽省合肥市高新区合欢路10号7号楼 电 话：0551-64466966 开户行：徽商银行股份有限公司合肥经济开发区支行 帐 号：223021347901000002 | O39: 增值税专用发票/增值税普通发票：维修费 | P39: 0.13
A40: 江西恒嘉信生物科技有限公司 | B40: 南昌 | C40: 华南区 | I40: 江西省南昌市南昌县莲塘北大道899号鹿鼎爱丁堡30栋106室 | J40: 18870083757 | K40: 夏子路 | L40: 915318704@qq.com | M40: 18870083757 | N40: 公司名：江西恒嘉信生物科技有限公司 地 址：江西省上饶经济技术开发戊兴业大道26号(盛奇光学产业园3栋7楼) 邮 编：334000 电 话：15870971288 开户行：中国工商银行股份有限公司广信旭日支行 账 号：1512004509000078626 | O40: 增值税专用发票/增值税普通发票：维修费或维护费 | P40: 0.13
...

Sheet 渠道承接方案信息
B1: 培训中心全称 | C1: 已授权课程方案 | D1: 课程讲师1（含工号） | E1: 课程讲师2（含工号） | F1: 课程讲师3（含工号） | G1: 课程讲师4（含工号） | H1: 课程讲师5（含工号） | I1: 课程讲师6（含工号）
B2: 郑州青旭医疗科技有限公司 | C2: 麻醉_麻醉机服务资质面授课程 | D2: 刘晓臣 | E2: 朱吾东
B3: 浙江英特百善医疗设备有限公司 | C3: 血球_血球M68&68P系列服务资质面授课程 | D3: 姜纪亮 | E3: 蒋国佳 | F3: 余杭君
B4: 浙江英特百善医疗设备有限公司 | C4: 血球_中端五分类服务资质面授课程 | D4: 许威
B5: 浙江英特百善医疗设备有限公司 | C5: 临床应用_血球_培训资质获取方案面授课程 | D5: 黄雪林 | E5: 罗春霖 | F5: 吴周阳 | G5: 李金陵
B6: 浙江英特百善医疗设备有限公司 | C6: （面授）临床应用_化学发光_培训资质获取方案面授课程 | D6: 韩春运
B7: 新疆九州通医疗科技有限公司 | C7: 血球_中端五分类服务资质面授课程
B8: 新疆九州通医疗科技有限公司 | C8: 血球_血球M68&68P系列服务资质面授课程
B9: 新疆九州通医疗科技有限公司 | C9: 生化_800系列服务资质面授课程 | D9: 汪飞亚
B10: 新疆九州通医疗科技有限公司 | C10: 生化_化学发光-2000i服务资质面授课程
B11: 新疆九州通医疗科技有限公司 | C11: （面授）临床应用_化学发光_培训资质获取方案面授课程 | D11: 陈柳姗
B12: 新疆九州通医疗科技有限公司 | C12: 临床应用_生化_培训资质获取方案面授课程 | D12: 陈慧兵
B13: 新疆九州通医疗科技有限公司 | C13: 临床应用_血球_培训资质获取方案面授课程 | D13: 颜裕洁
B14: 西安尚肯电子科技有限公司 | C14: 超声_彩超1服务资质面授课程 | D14: 刘轩 | E14: 成年
B15: 四川瑞孚医疗科技股份有限公司 | C15: 生化_2000速生化服务资质面授课程 | D15: 陈天路 | E15: 刘强
B16: 四川瑞孚医疗科技股份有限公司 | C16: 生化_化学发光-6000i系列服务资质面授课程 | D16: 王兴作 | E16: 肖睿
B17: 四川瑞孚医疗科技股份有限公司 | C17: （面授）临床应用_化学发光_培训资质获取方案面授课程 | D17: 刘林
B18: 四川精晶科技发展有限责任公司 | C18: 麻醉_麻醉机服务资质面授课程 | D18: 段利军
B19: 四川国科康仪医疗科技有限公司 | C19: 血球_血球M68&68P系列服务资质面授课程 | D19: 闵子强 | E19: 岳照海
B20: 四川国科康仪医疗科技有限公司 | C20: 血球_中端五分类服务资质面授课程 | D20: 龙刚
B21: 四川国科康仪医疗科技有限公司 | C21: 血球_血球M60系列服务资质面授课程 | D21: 张峻菠 | E21: 龙刚
B22: 四川国科康仪医疗科技有限公司 | C22: 临床应用_血球_培训资质获取方案面授课程 | D22: 汪洋 | E22: 周成龙 | F22: 谭辉
B23: 陕西沃尔克贸易有限公司 | C23: 生化_800系列服务资质面授课程 | D23: 张帅鹏
B24: 陕西沃尔克贸易有限公司 | C24: 临床应用_血球_培训资质获取方案面授课程 | D24: 张心 | E24: 秦江胜
B25: 陕西沃尔克贸易有限公司 | C25: 生化_化学发光-6000i系列服务资质面授课程
B26: 陕西沃尔克贸易有限公司 | C26: 临床应用_生化_培训资质获取方案面授课程 | D26: 占伟
B27: 陕西沃尔克贸易有限公司 | C27: （面授）临床应用_化学发光_培训资质获取方案面授课程 | D27: 魏萌 | E27: 顾蒙
B28: 陕西沃尔克贸易有限公司 | C28: 血球_中端五分类服务资质面授课程 | D28: 待考
B29: 陕西沃尔克贸易有限公司 | C29: 血球_血球M68&68P系列服务资质面授课程 | D29: 待考
B30: 陕西瑞孚医疗科技有限公司 | C30: （面授）凝血_场景化磁珠法仪器服务资质获取方案 | D30: 徐辉
B31: 南京贝登医疗股份有限公司 | C31: 三分类血球 | D31: 靳鹏云 | E31: 蔡壮 | F31: 张海军
B32: 南京贝登医疗股份有限公司 | C32: BC-5000 | D32: 靳鹏云 | E32: 蔡壮
B33: 南京贝登医疗股份有限公司 | C33: 低端超声 | D33: 靳鹏云 | E33: 吴良园
B34: 南京贝登医疗股份有限公司 | C34: 监护小产品 | D34: 吴良园 | E34: 张海军
B35: 南京贝登医疗股份有限公司 | C35: 低速生化 | D35: 靳鹏云 | E35: 蔡壮
B36: 辽宁医工技术服务有限公司 | C36: 血球_血球M68&68P系列服务资质面授课程 | D36: 王磊
B37: 辽宁医工技术服务有限公司 | C37: 临床应用_血球_培训资质获取方案面授课程 | D37: 李艳君 | E37: 金雪纯
B38: 辽宁医工技术服务有限公司 | C38: 血球_BC-75CRP/CS系列服务资质面授课程 | D38: 王磊
B39: 辽宁九诺生物科技有限公司 | C39: 生化_800系列服务资质面授课程 | D39: 周显明
B40: 辽宁九诺生物科技有限公司 | C40: 临床应用_生化_培训资质获取方案面授课程 | D40: 徐士文
...

Sheet 历史基础信息
A1: 培训中心全称 | B1: 分公司 | C1: 区域 | D1: 培训中心地址 | E1: 培训中心电话 | F1: 培训中心培训对接人 | G1: 对接人邮箱 | H1: 对接人手机 | I1: 收款信息 | J1: 发票类型 | K1: 税率 | L1: 备注
A2: 新疆九州通医疗科技有限公司 | B2: =IFERROR(_xlfn.XLOOKUP(A2,历史方案信息!$C$2:$C$151,历史方案信息!$B$2:$B$151,""),"") -> 新疆 | C2: =IFERROR(_xlfn.XLOOKUP(A2,历史方案信息!$C$2:$C$151,历史方案信息!$A$2:$A$151,""),"") -> 西北区 | D2: 新疆乌鲁木齐高新区（新市区）鲤鱼山北 路199号驰达-电子信息产业加速器1栋608号 | E2: 0991-3075000 | F2: 师灿灿 | G2: 1433825820@qq.com | H2: 13039457336 | I2: 单位名称:新疆中品医疗科技有限公司 税号: 91650104MA78W1CL2H 注册地址:新疆乌鲁木齐高新区（新市区）鲤鱼山北路199号驰达-电子信息产业加速器1栋501-504号 开户银行:招商银行乌鲁木齐北京路支行 账号: 991905464910601 行号:308881029067 | J2: 增值税专用发票/增值税普通发票：培训费 | K2: 0.06
A3: 兰州恺尔有商贸有限公司 | B3: =IFERROR(_xlfn.XLOOKUP(A3,历史方案信息!$C$2:$C$151,历史方案信息!$B$2:$B$151,""),"") -> 兰州 | C3: =IFERROR(_xlfn.XLOOKUP(A3,历史方案信息!$C$2:$C$151,历史方案信息!$A$2:$A$151,""),"") -> 西北区 | D3: 甘肃省兰州市城关区南滨河东路5198号名城广场1幢2单元14楼19室 | E3: 0931-8526183 | F3: 王洁 | G3: kry8526183@163.com | H3: 17797604947 | I3: 名称：兰州恺尔有商贸有限公司 税号：91627100MA7DC2JT0C 单位地址：甘肃省兰州市兰州新区绿地集团一期G地块渭河街3103号8A-19室 电话：09318526183 开户银行：中国建设银行兰州城关支行 银行账户：62050136000100001000 | J3: 增值税专用发票/增值税普通发票：维修费或维护费 | K3: 0.13 | L3: 公司属于一般纳税人，且不属于小型微利企业，无增值税及企业所得税优惠政策
A4: 成都瑞坤科技有限公司 | B4: =IFERROR(_xlfn.XLOOKUP(A4,历史方案信息!$C$2:$C$151,历史方案信息!$B$2:$B$151,""),"") -> 成都 | C4: =IFERROR(_xlfn.XLOOKUP(A4,历史方案信息!$C$2:$C$151,历史方案信息!$A$2:$A$151,""),"") -> 西南区 | D4: 四川省成都市武侯区武科西四路99号金地威新科创园3栋3楼301室 | E4: 028-87799602 | F4: 陈宏 | G4: 103045739@qq.com | H4: 18782285187 | I4: 公司名：南充市顺庆区吉哆商务信息咨询服务部(个体工商户) 开户行：中国工商银行股份有限公司南充石油南路支 行 账 号：2315539209100080846 | J4: 增值税专用发票/增值税普通发票：维修费 | K4: 0.01
A5: 博实医疗保健（上海）有限公司 | B5: =IFERROR(_xlfn.XLOOKUP(A5,历史方案信息!$C$2:$C$151,历史方案信息!$B$2:$B$151,""),"") -> 上海 | C5: =IFERROR(_xlfn.XLOOKUP(A5,历史方案信息!$C$2:$C$151,历史方案信息!$A$2:$A$151,""),"") -> 华东区 | D5: 上海市奉贤区环城北路1099号 | E5: 021-61213287 | F5: 卞小姐 | G5: bianlili@boshi-diagnostics.com | H5: 13761291149 | I5: 公司名：博实医疗保健（上海）有限公司 地 址：上海市金山区金山卫镇秋实路688号9幢（金山新材料孵化器) 电 话：021-67181810 开户行：工商银行徐汇裕德路支行 账 号：1001270209300105185 | J5: 增值税专用发票/增值税普通发票：维修费或技术服务费 | K5: 13%或6% | L5: 公司属于小规模纳税人，目前1%税收优惠政策截至到2020年12月31日，故今年开的所有发票税率均为1%
A6: 广州艾维迪生物技术有限公司 | B6: =IFERROR(_xlfn.XLOOKUP(A6,历史方案信息!$C$2:$C$151,历史方案信息!$B$2:$B$151,""),"") -> 广州 | C6: =IFERROR(_xlfn.XLOOKUP(A6,历史方案信息!$C$2:$C$151,历史方案信息!$A$2:$A$151,""),"") -> 华南区 | D6: 广州市番禺区东环街天保路6号易事达大厦一楼105号 | E6: - | F6: 杨锦婵 | G6: 3601907146@qq.com | H6: 15322031002 | I6: 名称：广州艾维迪生物技术有限公司 纳税人识别号：91440101MA59TP8L3N 地址：广州市番禺区东环街天保路6号105铺之三 电话：020-31046729 开户行：中国银行广州番禺巨大产业园支行 帐号：645772162272 | J6: 增值税专用发票:培训服务票 | K6: 0.06 | L6: -
A7: 湖北瑞智达科技有限公司 | B7: =IFERROR(_xlfn.XLOOKUP(A7,历史方案信息!$C$2:$C$151,历史方案信息!$B$2:$B$151,""),"") -> 武汉 | C7: =IFERROR(_xlfn.XLOOKUP(A7,历史方案信息!$C$2:$C$151,历史方案信息!$A$2:$A$151,""),"") -> 华东区 | D7: 武汉市东西湖区金山达到1312号金海工业园6楼培训室 | E7: 027-83266623 | F7: 加燕楠 | G7: 1173256815@qq.com | H7: 19071020885 | I7: 武汉鑫瑞丰华科贸有限公司 开户行：中国工商银行武汉海关支行 帐号:3202 1230 1910 0016 820 | J7: 增值税专用发票/增值税普通发票：培训服务费 | K7: 0.06 | L7: 2个教室
A8: 广西铂泓生物科技有限公司 | B8: =IFERROR(_xlfn.XLOOKUP(A8,历史方案信息!$C$2:$C$151,历史方案信息!$B$2:$B$151,""),"") -> 南宁 | C8: =IFERROR(_xlfn.XLOOKUP(A8,历史方案信息!$C$2:$C$151,历史方案信息!$A$2:$A$151,""),"") -> 西南区 | D8: 广西壮族自治区南宁市良庆区中国（广西）自由贸易试验区南宁片区华威路 16 号南向电子信息产业园 3 号楼 4 楼A-01、A-02室 | E8: 0771-4972859 | F8: 万雨雯 | G8: 3984112127@qq.com | H8: 18777184023 | I8: 公司名：广西铂泓生物科技有限公司 地址：中国（广西）自由贸易试验区南宁片区凯旋路9号海尔青啤（东盟）联合广场2号楼五层503号办公室 电话：0771-4972859 开户行：中国光大银行股份有限公司南宁分行 账号：78890188000660007 | J8: 增值税专用发票/增值税普通发票：培训费/维修费 | K8: 6%/13% | L8: 增值税一般纳税人
A9: 四川国科康仪医疗科技有限公司 | B9: =IFERROR(_xlfn.XLOOKUP(A9,历史方案信息!$C$2:$C$151,历史方案信息!$B$2:$B$151,""),"") -> 成都 | C9: =IFERROR(_xlfn.XLOOKUP(A9,历史方案信息!$C$2:$C$151,历史方案信息!$A$2:$A$151,""),"") -> 西南区 | D9: 四川省成都市金牛区沙河源街道金丰路106号量力医药健康城7号楼12楼 | E9: 028-87776785 | F9: 敖春花 | G9: 309751765@qq.com | H9: 13678119175 | I9: 名称：四川世纪同昌医疗科技发展有限公司 地址：四川省成都市金牛区友联一街8号12楼1206-1208号 邮编：610000 电话：028-87579357 开户银行：成都银行抚琴支行 账号：1001300000983113 | J9: 增值税专用发票/增值税普通发票：服务费 | K9: 0.13
A10: 河南迈德瑞医疗服务供应链有限公司 | B10: =IFERROR(_xlfn.XLOOKUP(A10,历史方案信息!$C$2:$C$151,历史方案信息!$B$2:$B$151,""),"") -> 郑州 | C10: =IFERROR(_xlfn.XLOOKUP(A10,历史方案信息!$C$2:$C$151,历史方案信息!$A$2:$A$151,""),"") -> 西北区 | D10: 河南省郑州经济技术开发区第七大街188号院3号楼2楼 | E10: 0371-63827260 | F10: 黄晴 | G10: huangqing@hnmdr.com | H10: 15003856589 | I10: 公司名：河南迈德瑞医疗服务供应链有限公司 地 址：郑州经济技术开发区第七大街188号院3号楼2楼 邮 编：450000 电 话：0371-63827260 开户行：招商银行股份有限公司郑州经开区支行 账 号：371905274710802 | J10: 增值税专用发票/增值税普通发票：咨询服务费 | K10: 0.06
A11: 瑞帆（沈阳）医疗器械销售服务有限公司 | B11: =IFERROR(_xlfn.XLOOKUP(A11,历史方案信息!$C$2:$C$151,历史方案信息!$B$2:$B$151,""),"") -> 沈阳 | C11: =IFERROR(_xlfn.XLOOKUP(A11,历史方案信息!$C$2:$C$151,历史方案信息!$A$2:$A$151,""),"") -> 东北区 | D11: 辽宁省沈阳市于洪区吉力湖街 228-1 号（21 门、22 门） | E11: 15840345732 | F11: 常艳玲 | G11: 1359995947@qq.com | H11: 15840345732 | I11: 单位名称：沈阳雅努斯商贸有限公司 开 户 行：中国光大银行沈阳金城支行 账 号：75670188000258883 地 址：辽宁省沈阳市于洪区阳光路26-1号（202） 电 话：024-31226855 纳税人识别号：912101145734966210 | J11: 增值税专用发票/增值税普通发票：维修费或维护费 | K11: 0.06
A12: 浙江英特百善医疗设备有限公司 | B12: =IFERROR(_xlfn.XLOOKUP(A12,历史方案信息!$C$2:$C$151,历史方案信息!$B$2:$B$151,""),"") -> 杭州 | C12: =IFERROR(_xlfn.XLOOKUP(A12,历史方案信息!$C$2:$C$151,历史方案信息!$A$2:$A$151,""),"") -> 华东区 | D12: 浙江省杭州市西湖区蒋村街道双龙街239号西投创智中心1号楼5层502室 | E12: 0571-87131103 | F12: 金芳 | G12: 1182784991@qq.com | H12: 17857071365 | I12: 公司名称： 浙江英特百善医疗设备有限公司 税务登记号：91330106079348885U 税务登记地址：浙江省杭州市西湖区蒋村街道双龙街239号西投创智中心1号楼5层502室 税务登记电话：0571-87131103 税务登记开户银行名称：中国工商银行股份有限公司杭州古墩路支行 税务登记银行账号：1202224909900169993 百善开户行行号：102331002495 | J12: 增值税专用发票 | K12: 0.06 | L12: 一般纳税人
A13: 广西讴健供应链管理集团有限公司 | B13: =IFERROR(_xlfn.XLOOKUP(A13,历史方案信息!$C$2:$C$151,历史方案信息!$B$2:$B$151,""),"") | C13: =IFERROR(_xlfn.XLOOKUP(A13,历史方案信息!$C$2:$C$151,历史方案信息!$A$2:$A$151,""),"") | D13: 南宁市江南区金凯路106号联东U谷南宁经开科技港标准厂房16号厂房5楼 | E13: 0771-4891028 | F13: 郭尧 | G13: pxzx@ojscg.com | H13: 19977196114 | I13: 公司名称：广西讴健供应链管理集团有限公司 地址：南宁市金凯路106号联东U谷南宁经开科技港标准厂房16号厂房101号房 邮 编：530031 电话：0771-4891028 开户行：中国银行南宁市桃源支行 账 号：618482498077 | J13: 增值税专用发票/增值税普通发票：维修费或维护费 | K13: 0.03
A14: 河南晟宝电子技术有限公司 | B14: =IFERROR(_xlfn.XLOOKUP(A14,历史方案信息!$C$2:$C$151,历史方案信息!$B$2:$B$151,""),"") -> 郑州 | C14: =IFERROR(_xlfn.XLOOKUP(A14,历史方案信息!$C$2:$C$151,历史方案信息!$A$2:$A$151,""),"") -> 西北区 | D14: 河南省郑州市高新区莲花街联东U谷-郑州高新国际企业港18号-2号楼501 | E14: 0371-55919089 | F14: 汪晓锋 | G14: 863637991@qq.com | H14: 15890058791 | I14: 开票资料 单 位 名 称：河南晟宝电子技术有限公司 纳税人识别号：91410100MA3X9WQH3B 地 址、电 话：河南省郑州市高新区莲花街联东U谷-郑州高新国际企业港18号-2号楼401 0371-55919089 开户行及账号：中国银行股份有限公司郑州高新技术开发区支行258549558281 | J14: 增值税专用发票/技术服务费 | K14: 0.06
A15: 安徽赛威思医疗供应链服务有限公司 | B15: =IFERROR(_xlfn.XLOOKUP(A15,历史方案信息!$C$2:$C$151,历史方案信息!$B$2:$B$151,""),"") -> 合肥 | C15: =IFERROR(_xlfn.XLOOKUP(A15,历史方案信息!$C$2:$C$151,历史方案信息!$A$2:$A$151,""),"") -> 华东区 | D15: 安徽省合肥市包河区上海路18号淮仁堂4楼8401室 | E15: 0551-62680075 | F15: 胡娟 | G15: 18712179581@163.com | H15: 18712179581 | I15: 公司名称：安徽赛威思医疗供应链服务有限公司 地 址：安徽省合肥市包河区上海路18号淮仁堂4楼8401室 邮 编：230000 电 话：0551-62680075 开户行：中国建设银行合肥银杏苑支行 账 号：34050145090600000167 | J15: 增值税专用发票/增值税普通发票：服务费或技术服务费 | K15: 0.06
A16: 科海同业河北医疗器械贸易有限公司 | B16: =IFERROR(_xlfn.XLOOKUP(A16,历史方案信息!$C$2:$C$151,历史方案信息!$B$2:$B$151,""),"") -> 石家庄 | C16: =IFERROR(_xlfn.XLOOKUP(A16,历史方案信息!$C$2:$C$151,历史方案信息!$A$2:$A$151,""),"") -> 华北区 | D16: 河北省石家庄市桥西区新石中路375号金石大厦C座7楼 | E16: 31183809982 | F16: 刘刚 | G16: 469997060@qq.com | H16: 17732120400 | I16: 科海同业河北医疗器械贸易有限公司开票信息 公司名称：科海同业河北医疗器械贸易有限公司 开户行：建行石家庄红旗大街支行 账 号：13050161560800000996 税 号：91130104MA0CX2RJ07 地 址：河北省石家庄市桥西区新石中路375号金石大厦C座7楼722-726室 电 话：0311-83809982 | J16: 增值税专用发票/增值税普通发票：维修费或技术服务咨询 | K16: 0.06 | L16: 公司是一般纳税人：维修费是13点 技术咨询服务是6点
A17: 四川瑞孚医疗科技股份有限公司 | B17: =IFERROR(_xlfn.XLOOKUP(A17,历史方案信息!$C$2:$C$151,历史方案信息!$B$2:$B$151,""),"") -> 成都 | C17: =IFERROR(_xlfn.XLOOKUP(A17,历史方案信息!$C$2:$C$151,历史方案信息!$A$2:$A$151,""),"") -> 西南区 | D17: 成都市锦江区创意工业园毕昇路468号创世纪大厦1栋30层 | E17: 18349375258 | F17: 王春艳 | G17: 936051093@qq.com | H17: 18349375258 | I17: 户名：四川瑞孚医疗科技股份有限公司 开户行：成都银行股份有限公司锦江工业园支行 银行账号：1001300001082677 纳税人识别号：91510100MAC4G1J97E 公司地址：四川省成都市锦江区创意工业园毕昇路466号、468号1栋30层1号 公司电话：028-85212668 | J17: 增值税专用发票：服务费或技术服务费 | K17: 0.06
A18: 甘肃赣陇医疗科技有限公司 | B18: =IFERROR(_xlfn.XLOOKUP(A18,历史方案信息!$C$2:$C$151,历史方案信息!$B$2:$B$151,""),"") | C18: =IFERROR(_xlfn.XLOOKUP(A18,历史方案信息!$C$2:$C$151,历史方案信息!$A$2:$A$151,""),"") | D18: 甘肃省兰州市安宁区沙井驿街道北滨河西路1272号（兰州国际家居建材博览城B1区第9幢301室） | E18: 15379020517 | F18: 程生宝 | G18: 2479419728@qq.com | H18: 15379020517 | I18: 公司名：甘肃赣陇医疗科技有限公司 地 址：甘肃省兰州市七里河区中天健11栋2201室 邮 编：730050 电 话：0931-7894298 开户行：交通银行兰州七里河支行 账 号：621060108013000133112 | J18: 增值税专用发票/增值税普通发票：培训费 | K18: 0.06
A19: 西安尚肯电子科技有限公司 | B19: =IFERROR(_xlfn.XLOOKUP(A19,历史方案信息!$C$2:$C$151,历史方案信息!$B$2:$B$151,""),"") -> 西安 | C19: =IFERROR(_xlfn.XLOOKUP(A19,历史方案信息!$C$2:$C$151,历史方案信息!$A$2:$A$151,""),"") -> 西北区 | D19: 陕西省西安市雁塔区高新区团结南路12号西安国际人才大厦A座1001室 | E19: 029-88451665 | F19: 成年 | G19: 1183439346@qq.com | H19: 18840389808 | I19: 公司名：西安尚肯电子科技有限公司 地 址：西安市高新区唐延南路十一号3幢1单元11627室 税号：9161 0131 3224 0244 08 邮 编：710000 电 话：029－88451665 开户行：中国银行股份有限公司西安逸翠园支行 账 号：1024 5129 5214 | J19: 培训费，专票 | K19: 0.06
A20: 四川精晶科技发展有限责任公司 | B20: =IFERROR(_xlfn.XLOOKUP(A20,历史方案信息!$C$2:$C$151,历史方案信息!$B$2:$B$151,""),"") -> 成都 | C20: =IFERROR(_xlfn.XLOOKUP(A20,历史方案信息!$C$2:$C$151,历史方案信息!$A$2:$A$151,""),"") -> 西南区 | D20: 四川省成都市金牛区蜀西路42号三泰魔方B2栋904室 | E20: 028-83178198 | F20: 臧鹏 | G20: 113317031@QQ.COM | H20: 13550241780 | J20: 增值税专用发票/增值税普通发票：维修费 | K20: 0.13 | L20: 公司属于一般纳税人，可以开具增值税专用发票，税率为13%。
A21: 广东美馗生物技术有限公司 | B21: =IFERROR(_xlfn.XLOOKUP(A21,历史方案信息!$C$2:$C$151,历史方案信息!$B$2:$B$151,""),"") | C21: =IFERROR(_xlfn.XLOOKUP(A21,历史方案信息!$C$2:$C$151,历史方案信息!$A$2:$A$151,""),"") | D21: 广东省广州市番禺区南村镇兴业大道488号群兴科创园A栋307室 | E21: 020-31052118 | F21: 区伟民 | G21: 499674663@QQ.com | H21: 13602820901 | I21: 公司名：广东美馗生物技术有限公司 地 址：广州市番禺区市桥街兴泰路264号基盛万科大厦A栋602室 邮 编：511400 电 话：02031052118 开户行：中国工商银行股份有限公司广州大石支行 账 号：3602074819100483913 | J21: 增税专票/普票 | K21: 0.06 | L21: 开票内容：技术服务费
A22: 吉林省鸿嘉医疗器械有限公司 | B22: =IFERROR(_xlfn.XLOOKUP(A22,历史方案信息!$C$2:$C$151,历史方案信息!$B$2:$B$151,""),"") -> 黑吉 | C22: =IFERROR(_xlfn.XLOOKUP(A22,历史方案信息!$C$2:$C$151,历史方案信息!$A$2:$A$151,""),"") -> 东北区 | D22: 吉林省长春市宽城区龙腾路1377号汇酉生物五楼会议室 | E22: 0431-88922378 | F22: 王颖 | G22: cchlkj@163.com | H22: 15584329559 | I22: 公司名称：吉林省鸿嘉医疗器械有限公司税 号：9122 0104 6833 7279 36开 户 行：中国工商银行长春同志街支行账 号：4200 2291 0920 0051 752 | J22: 增值税专用发票/增值税普通发票：维修费、服务费或现代服务 | K22: 13%或6%
A23: 辽宁医工技术服务有限公司 | B23: =IFERROR(_xlfn.XLOOKUP(A23,历史方案信息!$C$2:$C$151,历史方案信息!$B$2:$B$151,""),"") -> 沈阳 | C23: =IFERROR(_xlfn.XLOOKUP(A23,历史方案信息!$C$2:$C$151,历史方案信息!$A$2:$A$151,""),"") -> 东北区 | D23: 辽宁省沈阳市和平区文艺路11号902 | E23: 024-25258227 | F23: 田佳鹭 | G23: 2531008545@qq.com | H23: 18741035493 | I23: 公 司：辽宁医工技术服务有限公司 地 址：沈阳市和平区文艺路11号902 邮 编：110001 电 话：024-25258227 开户行：中国民生银行股份有限公司沈阳青年大街支行 账 号：641894345 | J23: 增值税专用发票/增值税普通发票：维修费或维护费 | K23: 0.06
A24: 辽宁九诺生物科技有限公司 | B24: =IFERROR(_xlfn.XLOOKUP(A24,历史方案信息!$C$2:$C$151,历史方案信息!$B$2:$B$151,""),"") -> 沈阳 | C24: =IFERROR(_xlfn.XLOOKUP(A24,历史方案信息!$C$2:$C$151,历史方案信息!$A$2:$A$151,""),"") -> 东北区 | D24: 沈阳市浑南区朗日街22号1门 | E24: 024-31810269 | F24: 张伟华 | G24: 122381661@qq.com | H24: 13130478603 | I24: 名称:沈阳卓康商贸有限公司 帐号：0618 4001 0400 23398 开户行：农业银行沈阳兴华支行 行号：103221018405 | J24: 增值税专用发票/增值税普通发票：维修费或维护费 | K24: 0.13
A25: 杭州华景医疗科技有限公司 | B25: =IFERROR(_xlfn.XLOOKUP(A25,历史方案信息!$C$2:$C$151,历史方案信息!$B$2:$B$151,""),"") -> 杭州 | C25: =IFERROR(_xlfn.XLOOKUP(A25,历史方案信息!$C$2:$C$151,历史方案信息!$A$2:$A$151,""),"") -> 华东区 | D25: 浙江省杭州市萧山区萧山经济技术开 发区启迪路 198 号 B1-1001-01 室 | E25: 15067157785 | F25: 金冠盛 | G25: hzxsjgs@163.com | H25: 15067157785 | I25: 单位全称 杭州华景医疗科技有限公司 税号 91330108MA28NFUK9G 开户银行 杭州银行萧山城厢支行 银行账号 3301040160016610662 地址 浙江省杭州市萧山区萧山经济技术开 发区启迪路 198 号 B1-1001-01 室 电话 0571-86712990 | J25: 增值税专用发票/增值税普通发票：服务费或技术服务费 | K25: 0.06
A26: 北京东南仪诚实验室设备有限公司 | B26: =IFERROR(_xlfn.XLOOKUP(A26,历史方案信息!$C$2:$C$151,历史方案信息!$B$2:$B$151,""),"") -> 北京 | C26: =IFERROR(_xlfn.XLOOKUP(A26,历史方案信息!$C$2:$C$151,历史方案信息!$A$2:$A$151,""),"") -> 华北区 | D26: 北京市海淀区杏石口路30号A区119号 | E26: 13311118969 | F26: 王川 | G26: 24160300@qq.com | H26: 13311118969 | I26: 公司名：北京东南仪诚实验室设备有限公司 地 址：北京市海淀区杏石口路30号A区307号 010-51668855 邮编：100195 税 号：911101087393532696 开户行及账号：工行西直门支行0200065009200031207 行号：102100006502 | J26: 增值税专用发票/增值税普通发票：咨询服务 | K26: 0.06
A27: 河北钧溢祥医疗科技有限公司 | B27: =IFERROR(_xlfn.XLOOKUP(A27,历史方案信息!$C$2:$C$151,历史方案信息!$B$2:$B$151,""),"") -> 石家庄 | C27: =IFERROR(_xlfn.XLOOKUP(A27,历史方案信息!$C$2:$C$151,历史方案信息!$A$2:$A$151,""),"") -> 华北区 | D27: 河北省唐山市高新技术产业园区火炬路410号联东U谷产业园10#-1 214-1 | F27: 肖付 | G27: 564246333@qq.com | H27: 18716075943 | I27: 河北钧溢祥医疗科技有限公司 纳税人识别号：91130293MACKWRQ19Q 地址：河北省唐山市高新技术产业园区火炬路410号联东U谷产业园10#-1 214-1 邮 编：063009 电话：131 8042 6580 开户行：招商银行股份有限公司唐山高新区支行 账号：315901218310701 联系人: 毛春媛 15175585716 | J27: 增值税专用发票/增值税普通发票：维修费或维护费 | K27: 0.03 | L27: 公司属于小规模纳税人，目前1%税收优惠政策截至到2020年12月31日，故今年开的所有发票税率均为1%
A28: 江西吉迈医疗科技有限公司 | B28: =IFERROR(_xlfn.XLOOKUP(A28,历史方案信息!$C$2:$C$151,历史方案信息!$B$2:$B$151,""),"") -> 南昌 | C28: =IFERROR(_xlfn.XLOOKUP(A28,历史方案信息!$C$2:$C$151,历史方案信息!$A$2:$A$151,""),"") -> 华南区 | D28: 江西省南昌市青山湖区北山路259号塞维莱科技城B10栋1楼 | E28: 0791-88107699 | F28: 胡威 | G28: 348933088@qq.com | H28: 13870966433 | I28: 公司名称：江西吉迈医疗科技有限公司 地址：南昌市青山湖区北山路259号塞维莱科技园B10栋 邮编：332000 电话：0791-88107699 开户行：邮储银行洪城大市场支行 帐号：936007010013318895 | J28: 增值税专用发票/增值税普通发票：维修费或维护费
A29: 湖南康锦元科技有限公司 | B29: =IFERROR(_xlfn.XLOOKUP(A29,历史方案信息!$C$2:$C$151,历史方案信息!$B$2:$B$151,""),"") -> 长沙 | C29: =IFERROR(_xlfn.XLOOKUP(A29,历史方案信息!$C$2:$C$151,历史方案信息!$A$2:$A$151,""),"") -> 华南区 | D29: 湖南省长沙市岳麓区麓松路489号海凭国际大厦C2栋818室 | E29: 0731-86459660 | F29: 徐锋彬 | G29: ykylpx@163.com | H29: 13574115681 | I29: 公司名：湖南康锦元科技有限公司 地址：长沙高新开发区谷苑路229号海凭园2栋813房 邮编：410000 电话：0731-88805296 开户行：湖南银行股份有限公司长沙东塘支行 8121 0309 0000 07567 | J29: 增值税专用发票/增值税普通发票：培训费 | K29: 0.06 | L29: /
A30: 海南凯曼生物科技有限公司 | B30: =IFERROR(_xlfn.XLOOKUP(A30,历史方案信息!$C$2:$C$151,历史方案信息!$B$2:$B$151,""),"") -> 海南 | C30: =IFERROR(_xlfn.XLOOKUP(A30,历史方案信息!$C$2:$C$151,历史方案信息!$A$2:$A$151,""),"") -> 华南区 | D30: 海南省海口市龙华区南海大道100号美国工业村2-7单元二楼 | E30: 0898-68545586 | F30: 符业明 | G30: 332101335@qq.com | H30: 13876685747 | I30: 单位：海南凯曼生物科技有限公司 银行：中国工商银行股份有限公司海口海秀支行 银行帐号：2201021009200141553 纳税号： 91460000MA5TBBRF74 | J30: 增值税专用发票/增值税普通发票：维修费或技术服务费 | K30: 0.13
A31: 深圳市迈加生物医疗有限公司 | B31: =IFERROR(_xlfn.XLOOKUP(A31,历史方案信息!$C$2:$C$151,历史方案信息!$B$2:$B$151,""),"") | C31: =IFERROR(_xlfn.XLOOKUP(A31,历史方案信息!$C$2:$C$151,历史方案信息!$A$2:$A$151,""),"") | D31: 广东省惠州市云山西路2号（帝景国际商务中心C座1925室） | E31: 0755-23774060 | F31: 詹君 | G31: 823226784@qq.com | H31: 18123650463 | I31: 公司名：深圳市迈加生物医疗有限公司 地址：深圳市前海深港合作区前湾一路1号A栋201室（入驻深圳市前海商务秘书有限公司） 邮编：518000 电话：0755-23764330 开户行：中国农业银行深圳八卦岭支行 账号：41004800040024027 | J31: 增值税专用发票/增值税普通发票：服务费、技术咨询费 | K31: 0.06
A32: 济南逸兴恒运电子科技有限公司 | B32: =IFERROR(_xlfn.XLOOKUP(A32,历史方案信息!$C$2:$C$151,历史方案信息!$B$2:$B$151,""),"") -> 济南 | C32: =IFERROR(_xlfn.XLOOKUP(A32,历史方案信息!$C$2:$C$151,历史方案信息!$A$2:$A$151,""),"") -> 华北区 | D32: 山东省济南市历下区华夏福地3号楼1单元201室 | E32: 0531-82916508 | F32: 王辉 | G32: wh163631@163.com | H32: 18660812091 | I32: 公司名：山东智信医疗设备有限公司 地 址：山东省济南市商河县玉皇庙镇白玉路与玉皇路交叉口公交始末站3楼311室 邮 编：251600 电 话：0531-82916508 开户行：招商银行股份有限公司济南解放路支行 账 号：531905488710401 | J32: 增值税专用发票：培训费 | K32: 0.06
A33: 内蒙古众智医工技术服务有限公司 | B33: =IFERROR(_xlfn.XLOOKUP(A33,历史方案信息!$C$2:$C$151,历史方案信息!$B$2:$B$151,""),"") | C33: =IFERROR(_xlfn.XLOOKUP(A33,历史方案信息!$C$2:$C$151,历史方案信息!$A$2:$A$151,""),"") | D33: 内蒙古呼和浩特市新城区腾飞北路15号606室 | E33: 13847134917 | F33: 杨晨光 | G33: 767160131@qq.com | H33: 15148213495 | I33: 公司名称：内蒙古众智医工技术服务有限公司 纳税人识别号：91150105MA7FNGEF4T 银行账号：4719 0219 6110 801 开户行：招商银行股份有限公司呼和浩特分行营业部 行号：3081 9103 6114 地址：内蒙古自治区呼和浩特市赛罕区绿地领海大厦B座1109 电话：18347407450 邮编010000 | J33: 增值税专用发票/增值税普通发票：维修费或维护费 | K33: 0.03 | L33: 公司属于小规模纳税人，目前1%税收优惠政策。按需要可开3%增值税专票或普票。
A34: 云南晟新达医疗器械有限公司 | B34: =IFERROR(_xlfn.XLOOKUP(A34,历史方案信息!$C$2:$C$151,历史方案信息!$B$2:$B$151,""),"") | C34: =IFERROR(_xlfn.XLOOKUP(A34,历史方案信息!$C$2:$C$151,历史方案信息!$A$2:$A$151,""),"") | D34: 云南省昆明市盘龙区北京路延长线住佳商宇4幢8层2号 | E34: 0871-65382116 | F34: 熊济 | G34: 363377906@qq.com | H34: 13888203183 | I34: 公司名：云南靖都医疗器械有限公司 地 址：云南省昆明市盘龙区北京路延长线住佳商宇4幢8层2号 邮 编：650000 电 话：0871-65382116 开户行：中国建设银行股份有限公司昆明凤凰城支行 账 号：53050190504000000013 | J34: 增值税专用发票/增值税普通发票：维修费或维护费 | K34: 0.13
A35: 成都泓然明吉商贸有限公司 | B35: =IFERROR(_xlfn.XLOOKUP(A35,历史方案信息!$C$2:$C$151,历史方案信息!$B$2:$B$151,""),"") -> 成都 | C35: =IFERROR(_xlfn.XLOOKUP(A35,历史方案信息!$C$2:$C$151,历史方案信息!$A$2:$A$151,""),"") -> 西南区 | D35: 成都市青羊区光华北五路266号新兴产业示范大厦3栋11楼 | E35: 028-86150103 | F35: 唐萍 | G35: cdhrmj@126.com | H35: 15823546260 | I35: 名称：成都泓然明吉商贸有限公司 纳税人识别号：91510105350558848T 地址、电话：成都市青羊区蜀金路1号3栋19层1905号 86150103 开户行及帐号：招商银行成都分行金沙支行 128906494810101 | J35: 增值税专用发票/增值税普通发票：维修费或维护费 | K35: 0.13 | L35: /
A36: 南京贝登医疗股份有限公司 | B36: =IFERROR(_xlfn.XLOOKUP(A36,历史方案信息!$C$2:$C$151,历史方案信息!$B$2:$B$151,""),"") -> 南京 | C36: =IFERROR(_xlfn.XLOOKUP(A36,历史方案信息!$C$2:$C$151,历史方案信息!$A$2:$A$151,""),"") -> 华东区 | D36: 江苏省南京市秦淮区永丰大道36号01栋10楼 | E36: 025-68538253 | F36: 刘会奇 | G36: simba.liu@vedeng.com | H36: 13913040353 | I36: 公司名：南京贝登医疗股份有限公司 地址：南京市秦淮区永顺路2号2幢三楼301室 邮编：210014 电 话：025-68538253 开户行： 中国建设银行江苏南京中山南路支行 账号： 32001881236052503686 | J36: 增值税普通发票：维修费或维护费 | K36: 0.03 | L36: 公司属于一般纳税人
A37: 郑州青旭医疗科技有限公司 | B37: =IFERROR(_xlfn.XLOOKUP(A37,历史方案信息!$C$2:$C$151,历史方案信息!$B$2:$B$151,""),"") -> 郑州 | C37: =IFERROR(_xlfn.XLOOKUP(A37,历史方案信息!$C$2:$C$151,历史方案信息!$A$2:$A$151,""),"") -> 西北区 | D37: 河南省郑州市管城回族区经开第七大街与经北四路交叉口188号院北楼4楼407室 | E37: 0371-66337061 | F37: 郭啸 | G37: 18614962807@163.com | H37: 18614962807 | I37: 单位名称：郑州青旭医疗科技有限公司 税号：91410104MA9G002781 地址：河南省郑州市管城回族区城东南路55号2号楼2层209号 电话：13213261005 银行名称：招商银行股份有限公司郑州二里岗支行 账号：371908013610902 | J37: 增值税专用发票/增值税普通发票 | K37: 0.06
A38: 沈阳柏诺医疗电子科技有限公司 | B38: =IFERROR(_xlfn.XLOOKUP(A38,历史方案信息!$C$2:$C$151,历史方案信息!$B$2:$B$151,""),"") | C38: =IFERROR(_xlfn.XLOOKUP(A38,历史方案信息!$C$2:$C$151,历史方案信息!$A$2:$A$151,""),"") | D38: 辽宁省沈阳市浑南区浑南二路6-28号1801 | E38: 024-31607646 | F38: 李丹 | G38: 524063673@qq.com | H38: 15998351074 | I38: 公司名称：沈阳柏诺医疗电子科技有限公司 纳税人识别号：91210112MA7JNT3C93 地址：辽宁省沈阳市浑南区浑南二路6-28号（1-18-1、1-18-11） 电话：13904050810 开户行：招商银行股份有限公司沈阳新世界支行 账号：124910013710301 | J38: 增值税专用发票/增值税普通发票：维修费或维护费 | K38: 0.13 | L38: 公司属于一般纳税人
A39: 安徽蓝创生物科技有限公司 | B39: =IFERROR(_xlfn.XLOOKUP(A39,历史方案信息!$C$2:$C$151,历史方案信息!$B$2:$B$151,""),"") -> 合肥 | C39: =IFERROR(_xlfn.XLOOKUP(A39,历史方案信息!$C$2:$C$151,历史方案信息!$A$2:$A$151,""),"") -> 华东区 | D39: 安徽省合肥市蜀山区科学大道与合欢路交口合创产业园7D | E39: 0551-64466966 | F39: 李龙 | G39: 812640480@qq.com | H39: 17333079798 | I39: 安徽蓝创生物科技有限公司 税 号：91340111MA2TU3PJ33 地 址：安徽省合肥市高新区合欢路10号7号楼 电 话：0551-64466966 开户行：徽商银行股份有限公司合肥经济开发区支行 帐 号：223021347901000002 | J39: 增值税专用发票/增值税普通发票：维修费 | K39: 0.13
A40: 江西恒嘉信生物科技有限公司 | B40: =IFERROR(_xlfn.XLOOKUP(A40,历史方案信息!$C$2:$C$151,历史方案信息!$B$2:$B$151,""),"") -> 南昌 | C40: =IFERROR(_xlfn.XLOOKUP(A40,历史方案信息!$C$2:$C$151,历史方案信息!$A$2:$A$151,""),"") -> 华南区 | D40: 江西省南昌市南昌县莲塘北大道899号鹿鼎爱丁堡30栋106室 | E40: 18870083757 | F40: 夏子路 | G40: 915318704@qq.com | H40: 18870083757 | I40: 公司名：江西恒嘉信生物科技有限公司 地 址：江西省上饶经济技术开发戊兴业大道26号(盛奇光学产业园3栋7楼) 邮 编：334000 电 话：15870971288 开户行：中国工商银行股份有限公司广信旭日支行 账 号：1512004509000078626 | J40: 增值税专用发票/增值税普通发票：维修费或维护费 | K40: 0.13
...

Sheet 历史方案信息
A1: 区域 | B1: 分公司 | C1: 培训中心全称 | D1: 申请授权的产品 | E1: 授权面授课程 | F1: 渠道服务等级 | G1: 签约类型 | H1: 渠道讲师 | I1: 样机 | J1: 签约顺序 | K1: 备注
A2: 西北区 | B2: 郑州 | C2: 郑州青旭医疗科技有限公司 | D2: 麻醉机 | E2: 麻醉_麻醉机服务资质面授课程 | F2: V3.0 | G2: 销售用服同签 | H2: 刘晓臣、朱吾东 | I2: WATO EX-55/WATO A7 | J2: 第一批认证
A3: 华东区 | B3: 杭州 | C3: 浙江英特百善医疗设备有限公司 | D3: 血球M68系列 | E3: 血球_血球M68&68P系列服务资质面授课程 | F3: V3.0 | G3: 销售用服同签 | H3: 姜纪亮、蒋国佳、余杭君 | I3: BC-6800 | J3: 第一批认证
A4: 华东区 | B4: 杭州 | C4: 浙江英特百善医疗设备有限公司 | D4: 中端五分类 | E4: 血球_中端五分类服务资质面授课程 | F4: V3.0 | G4: 销售用服同签 | H4: 许威 | I4: BC-5800、BC-5390CRP | J4: 第一批认证
A5: 华东区 | B5: 杭州 | C5: 浙江英特百善医疗设备有限公司 | D5: 血球培训资质 | E5: 临床应用_血球_培训资质获取方案面授课程 | F5: V3.0 | G5: 销售用服同签 | H5: 黄雪林、罗春霖、吴周阳、李金陵 | I5: BC-6800 | J5: 第一批认证
A6: 华东区 | B6: 杭州 | C6: 浙江英特百善医疗设备有限公司 | D6: 发光培训资质 | E6: （面授）临床应用_化学发光_培训资质获取方案面授课程 | F6: V3.0 | G6: 销售用服同签 | H6: 韩春运 | I6: CL-2000I | J6: 第一批认证
A7: 西北区 | B7: 新疆 | C7: 新疆九州通医疗科技有限公司 | D7: 中端五分类 | E7: 血球_中端五分类服务资质面授课程 | F7: V2.0 | G7: 销售用服同签 | H7: 待考 | I7: BC-5800、BC-5390CRP | J7: 第二批认证 | K7: 更名：新疆中品医疗科技有限公司
A8: 西北区 | B8: 新疆 | C8: 新疆九州通医疗科技有限公司 | D8: 血球M68系列 | E8: 血球_血球M68&68P系列服务资质面授课程 | F8: V2.0 | G8: 销售用服同签 | H8: 待考 | I8: BC-6800 | J8: 第二批认证 | K8: 更名：新疆中品医疗科技有限公司
A9: 西北区 | B9: 新疆 | C9: 新疆九州通医疗科技有限公司 | D9: 800速生化 | E9: 生化_800系列服务资质面授课程 | F9: V2.0 | G9: 销售用服同签 | H9: 汪飞亚 | I9: BS-800 | J9: 第二批认证 | K9: 更名：新疆中品医疗科技有限公司
A10: 西北区 | B10: 新疆 | C10: 新疆九州通医疗科技有限公司 | D10: CL-2000i | E10: 生化_化学发光-2000i服务资质面授课程 | F10: V2.0 | G10: 销售用服同签 | H10: 待考 | I10: CL-2000I | J10: 第二批认证 | K10: 更名：新疆中品医疗科技有限公司
A11: 西北区 | B11: 新疆 | C11: 新疆九州通医疗科技有限公司 | D11: 发光培训资质 | E11: （面授）临床应用_化学发光_培训资质获取方案面授课程 | F11: V2.0 | G11: 销售用服同签 | H11: 陈柳姗 | I11: CL-2000I | J11: 第二批认证 | K11: 更名：新疆中品医疗科技有限公司
A12: 西北区 | B12: 新疆 | C12: 新疆九州通医疗科技有限公司 | D12: 生化培训资质 | E12: 临床应用_生化_培训资质获取方案面授课程 | F12: V2.0 | G12: 销售用服同签 | H12: 陈慧兵 | I12: BS-800 | J12: 第二批认证 | K12: 更名：新疆中品医疗科技有限公司
A13: 西北区 | B13: 新疆 | C13: 新疆九州通医疗科技有限公司 | D13: 血球培训资质 | E13: 临床应用_血球_培训资质获取方案面授课程 | F13: V2.0 | G13: 销售用服同签 | H13: 颜裕洁 | I13: BC-6800 | J13: 第二批认证 | K13: 更名：新疆中品医疗科技有限公司
A14: 西北区 | B14: 西安 | C14: 西安尚肯电子科技有限公司 | D14: 彩超1 | E14: 超声_彩超1服务资质面授课程 | F14: V3.0 | G14: 销售用服同签 | H14: 刘轩、成年 | I14: DC-80、DC-8、DC-60、M9 | J14: 第二批认证
A15: 西南区 | B15: 成都 | C15: 四川瑞孚医疗科技股份有限公司 | D15: 2000速生化 | E15: 生化_2000速生化服务资质面授课程 | F15: V3.0 | G15: 销售用服同签 | H15: 陈天路、刘强 | I15: BS-2000 | J15: 第一批认证
A16: 西南区 | B16: 成都 | C16: 四川瑞孚医疗科技股份有限公司 | D16: CL-6000i | E16: 生化_化学发光-6000i系列服务资质面授课程 | F16: V3.0 | G16: 销售用服同签 | H16: 王兴作、肖睿 | I16: CL-6000I | J16: 第一批认证
A17: 西南区 | B17: 成都 | C17: 四川瑞孚医疗科技股份有限公司 | D17: 发光培训资质 | E17: （面授）临床应用_化学发光_培训资质获取方案面授课程 | F17: V3.0 | G17: 销售用服同签 | H17: 刘林 | I17: CL-6000I | J17: 第一批认证
A18: 西南区 | B18: 成都 | C18: 四川精晶科技发展有限责任公司 | D18: 麻醉机 | E18: 麻醉_麻醉机服务资质面授课程 | F18: V2.0 | G18: 销售用服同签 | H18: 段利军 | I18: A7，WATO EX-65，WATO EX-65PRO | J18: 第一批认证
A19: 西南区 | B19: 成都 | C19: 四川国科康仪医疗科技有限公司 | D19: 血球M68系列 | E19: 血球_血球M68&68P系列服务资质面授课程 | F19: V3.0 | G19: 销售用服同签 | H19: 闵子强、岳照海 | I19: CAL8000、BC6800、BC6900、BC6600 | J19: 第一批认证
A20: 西南区 | B20: 成都 | C20: 四川国科康仪医疗科技有限公司 | D20: 中端五分类 | E20: 血球_中端五分类服务资质面授课程 | F20: V3.0 | G20: 销售用服同签 | H20: 龙刚 | I20: BC5390CRP、BC5600 | J20: 第一批认证
A21: 西南区 | B21: 成都 | C21: 四川国科康仪医疗科技有限公司 | D21: 血球M60系列 | E21: 血球_血球M60系列服务资质面授课程 | F21: V3.0 | G21: 销售用服同签 | H21: 张峻菠、龙刚 | I21: BC6000 | J21: 第一批认证
A22: 西南区 | B22: 成都 | C22: 四川国科康仪医疗科技有限公司 | D22: 血球培训资质 | E22: 临床应用_血球_培训资质获取方案面授课程 | F22: V3.0 | G22: 销售用服同签 | H22: 汪洋、周成龙、谭辉 | I22: CAL8000、BC6800、BC6900、BC6600 | J22: 第一批认证
A23: 西北区 | B23: 西安 | C23: 陕西沃尔克贸易有限公司 | D23: 800速生化 | E23: 生化_800系列服务资质面授课程 | F23: V3.0 | G23: 销售用服同签 | H23: 张帅鹏 | I23: BS-800/BS-2000 | J23: 第一批认证
A24: 西北区 | B24: 西安 | C24: 陕西沃尔克贸易有限公司 | D24: 血球培训资质 | E24: 临床应用_血球_培训资质获取方案面授课程 | F24: V3.0 | G24: 销售用服同签 | H24: 张心、秦江胜 | I24: BC-6700/BC-6800PLUS | J24: 第一批认证
A25: 西北区 | B25: 西安 | C25: 陕西沃尔克贸易有限公司 | D25: CL-6000i | E25: 生化_化学发光-6000i系列服务资质面授课程 | F25: V3.0 | G25: 销售用服同签 | H25: 待考 | I25: CL-6000I | J25: 第一批认证
... A37: 东北区 | B37: 沈阳 | C37: 辽宁医工技术服务有限公司 | D37: 血球培训资质 | E37: 临床应用_血球_培训资质获取方案面授课程 | F37: V3.0 | G37: 销售用服同签 | H37: 李艳君、金雪纯 | I37: BC-6800 | J37: 第一批认证
A38: 东北区 | B38: 沈阳 | C38: 辽宁医工技术服务有限公司 | D38: 血球75系列 | E38: 血球_BC-75CRP/CS系列服务资质面授课程 | F38: V3.0 | G38: 销售用服同签 | H38: 王磊 | I38: BC-75CS | J38: 第一批认证 | K38: 新增
A39: 东北区 | B39: 沈阳 | C39: 辽宁九诺生物科技有限公司 | D39: 800速生化 | E39: 生化_800系列服务资质面授课程 | F39: V2.0 | G39: 销售用服同签 | H39: 周显明 | I39: BS-800M | J39: 第一批认证
A40: 东北区 | B40: 沈阳 | C40: 辽宁九诺生物科技有限公司 | D40: 生化培训资质 | E40: 临床应用_生化_培训资质获取方案面授课程 | F40: V2.0 | G40: 销售用服同签 | H40: 徐士文 | I40: BS-800 | J40: 第一批认证
A41: 东北区 | B41: 沈阳 | C41: 辽宁九诺生物科技有限公司 | D41: 中端生化 | E41: 生化_中端生化服务资质面授课程 | F41: V2.0 | G41: 销售用服同签 | H41: 周显明 | I41: BS-620 | J41: 第一批认证
A42: 西北区 | B42: 兰州 | C42: 兰州恺尔有商贸有限公司 | D42: 发光培训资质 | E42: （面授）临床应用_化学发光_培训资质获取方案面授课程 | F42: V2.0 | G42: 销售用服同签 | H42: 杨吉荣 | I42: CL-1000I | J42: 第二批认证
A43: 西北区 | B43: 兰州 | C43: 兰州恺尔有商贸有限公司 | D43: CL-1000i | E43: 生化_化学发光-1000i服务资质面授课程 | F43: V2.0 | G43: 销售用服同签 | H43: 待考 | I43: CL-1000I | J43: 第二批认证
A44: 西北区 | B44: 兰州 | C44: 兰州恺尔有商贸有限公司 | D44: CL-2000i | E44: 生化_化学发光-2000i服务资质面授课程 | F44: V2.0 | G44: 销售用服同签 | H44: 张玉磊 | I44: CL-2000I | J44: 第二批认证
A45: 西北区 | B45: 兰州 | C45: 兰州恺尔有商贸有限公司 | D45: CL-6000i | E45: 生化_化学发光-6000i系列服务资质面授课程 | F45: V2.0 | G45: 销售用服同签 | H45: 张玉磊 | I45: CL-6000I | J45: 第二批认证
A46: 西南区 | B46: 昆明 | C46: 昆明康骐科技有限公司 | D46: 新生儿呼吸机 | E46: 麻醉_呼吸机（新生儿）服务资质面授课程 | F46: V3.0 | G46: 销售用服同签 | H46: 待考 | I46: NB350 | J46: 新增认证 | K46: 新增
A47: 西南区 | B47: 昆明 | C47: 昆明康骐科技有限公司 | D47: 无创呼吸机 | E47: 麻醉_无创呼吸机服务资质面授课程 | F47: V3.0 | G47: 销售用服同签 | H47: 待考 | I47: SV70 | J47: 新增认证 | K47: 新增
A48: 华北区 | B48: 石家庄 | C48: 科海同业河北医疗器械贸易有限公司 | D48: 生化培训资质 | E48: 临床应用_生化_培训资质获取方案面授课程 | F48: V3.0 | G48: 销售用服同签 | H48: 刘刚、宁瑶 | I48: BS-830 | J48: 第一批认证
A49: 华北区 | B49: 石家庄 | C49: 科海同业河北医疗器械贸易有限公司 | D49: 发光培训资质 | E49: （面授）临床应用_化学发光_培训资质获取方案面授课程 | F49: V3.0 | G49: 销售用服同签 | H49: 刘刚 | I49: CL-1000I | J49: 第一批认证
A50: 华北区 | B50: 石家庄 | C50: 科海同业河北医疗器械贸易有限公司 | D50: CL-1000i | E50: 生化_化学发光-1000i服务资质面授课程 | F50: V3.0 | G50: 销售用服同签 | H50: 张阔 | I50: CL-1000I | J50: 第一批认证
A51: 华北区 | B51: 石家庄 | C51: 科海同业河北医疗器械贸易有限公司 | D51: 中端生化 | E51: 生化_中端生化服务资质面授课程 | F51: V3.0 | G51: 销售用服同签 | H51: 赵强 | I51: BS-480 | J51: 第一批认证
...

Sheet 基础信息
G1: 申请授权的产品 | H1: 课程方案
F2: 1 | G2: 2000速生化 | H2: 生化_2000速生化服务资质面授课程
F3: 2 | G3: 800速生化 | H3: 生化_800系列服务资质面授课程
F4: 3 | G4: BC-5000 | H4: BC-5000
F5: 4 | G5: CL-1000i | H5: 生化_化学发光-1000i服务资质面授课程
F6: 5 | G6: CL-2000i | H6: 生化_化学发光-2000i服务资质面授课程
F7: 6 | G7: CL-6000i | H7: 生化_化学发光-6000i系列服务资质面授课程
F8: 7 | G8: 三分类血球 | H8: 三分类血球
F9: 8 | G9: 中端五分类 | H9: 血球_中端五分类服务资质面授课程
F10: 9 | G10: 中端凝血 | H10: （面授）凝血系列_中端凝血服务资质获取方案
F11: 10 | G11: 中端生化 | H11: 生化_中端生化服务资质面授课程
F12: 11 | G12: 低端凝血 | H12: （面授）凝血_场景化磁珠法仪器服务资质获取方案
F13: 12 | G13: 低端超声 | H13: 低端超声
... F29: 28 | G29: 麻醉机 | H29: 麻醉_麻醉机服务资质面授课程
